Workbook

Sheet Read me
B2: SpendIQ — proving the numbers on screen
B3: Every figure the screens display, traced to the records it came from and rebuilt from scratch.
B6: What this proves | C6: That each number on a SpendIQ screen is the number its underlying records actually produce — and shows the calculation, so you can check it rather than take it on trust.
B7: Where the screen values came from | C7: They are the product's own output. The real adapter and formatting code that runs in the browser was executed against live backend responses, and the resulting display strings were captured verbatim. Nothing on the 'On screen' sheet was retyped, rounded or approximated by hand.
B8: How each one was checked | C8: Three independent readings had to agree: what the screen renders, what the backend served, and what the raw records add up to when rebuilt from scratch. The rebuild deliberately avoids the product's own queries — if it reused them, a wrong query would agree with itself and prove nothing.
B9: Why the totals are formulas | C9: Nothing here is a pasted number. The source records are listed in full and every total, conversion, share and percentage is a live Excel formula over them. Click any total to see what it adds up; change a source row and it moves.
B11: Start here | C11: 'On screen' — each figure, what it displays, where it comes from, how it is calculated, and the rebuild that confirms it. Then 'Findings' for what the audit turned up and what was done about it.
B13: Data source | C13: Database bp_sqldb, schema proc — the 51-invoice extracted corpus (the gateway now defaults to bp_testdb).
B14: Exchange rates | C14: One shared snapshot taken 2026-07-27T14:26:47.300129+00:00. Rates are USD-quoted: units of currency per 1 USD, so converting into dollars divides.
B15: Corpus at time of audit | C15: 51 invoices · 45 quote records (29 quotes) · 39 purchase orders · 123 suppliers · 14 tracked deals
B17: Where a screen shows a dash | C17: Some figures are deliberately not printed. The headline spend is a dash because the corpus spans two currencies and there is no honest single as-billed total — the split is shown beneath it and the currency selector converts on demand. One quote's amount is withheld because its own tax line contradicts it. A dash here is a refusal to state something unproven, not a missing value.
B18: What this does NOT cover | C18: Whether each document was read correctly from its original PDF. This proves the screens faithfully represent the stored records; it does not prove the records faithfully represent the paperwork. That needs a separate check against source files — and finding 2 is what that gap looks like when it surfaces.
B19: Scale | C19: This corpus is 51 invoices. That is enough to prove the calculations are right; it is not enough to prove behaviour at customer volume.
B21: Sheets
B22: On screen | C22: Every displayed figure, its calculation, and the rebuild that proves it.
B23: Findings | C23: What the audit turned up, each marked fixed, contained or a decision for you.
B24: Invoices | C24: All invoice records, with the screens' spend blocks rebuilt as live formulas.
B25: FX rates | C25: The one rate snapshot every conversion uses.
B26: Spend by month | C26: The chart series, reconciled to the headline.
B27: Quotes | C27: Quote records by underlying quote — the revision-counting evidence.
B28: Deals | C28: Deal roll-ups and the spend that reaches no deal.
B29: Screen coverage | C29: Which screens are real data and which are still demo content.

Sheet On screen
A1: Every figure the screens display, and how it is calculated
A2: 'Shown on screen' is the product's own output — captured by running its real adapter and formatting code over live data, not retyped. 'Rebuilt here' is a live formula over the source sheets. Where the two agree, the figure is proven. Click any cell in the rebuild column to see the arithmetic.
A6: Screen | B6: What you see | C6: Shown on screen | D6: The number behind it | E6: Where it comes from | F6: How it is calculated | G6: Rebuilt here | H6: Agrees
A7: Dashboard | B7: Invoiced spend | C7: — | E7: metrics.totalSpend | F7: Deliberately blank. The corpus spans two currencies, so there is no single as-billed total to print; the split is shown beneath instead, and the currency selector converts on demand. | H7: n/a
A8: Dashboard | B8: …its sub-line | C8: £1.8M + $97.5K | D8: 1824950.4 | E8: metrics.spendByCurrency | F8: Each currency totalled separately and joined with a plus. No conversion, so nothing is assumed. | G8: ='Invoices'!B63 | H8: =IF(AND(ISNUMBER(D8),ISNUMBER(G8)),IF(ABS(D8-G8)<0.05,"yes","NO"),"see note")
A9: Dashboard | B9: Spend under management | C9: 98.1% | D9: 98.1 | E9: metrics.spendUnderManagement | F9: Invoiced spend backed by a purchase order, divided by all invoiced spend. Both sides converted on the same live rate, so the ratio compares like with like. | G9: ='Invoices'!B67 | H9: =IF(AND(ISNUMBER(D9),ISNUMBER(G9)),IF(ABS(D9-G9)<0.05,"yes","NO"),"see note")
A10: Dashboard | B10: Savings identified | C10: £0 | D10: 0 | E10: metrics.savingsIdentified | F10: Sum of financial impact across opportunity records. There are none yet, so this is a measured zero rather than a placeholder. | G10: 0 | H10: =IF(AND(ISNUMBER(D10),ISNUMBER(G10)),IF(ABS(D10-G10)<0.05,"yes","NO"),"see note")
A11: Dashboard | B11: Suppliers | C11: 123 | D11: 123 | E11: metrics.supplierCount | F11: Every supplier on the master list, whether or not they have billed. | G11: 123 | H11: =IF(AND(ISNUMBER(D11),ISNUMBER(G11)),IF(ABS(D11-G11)<0.05,"yes","NO"),"see note")
A12: Dashboard | B12: …invoiced | C12: 19 invoiced | D12: 19 | E12: metrics.suppliersWithSpend | F12: Distinct suppliers appearing on an invoice. Four invoices carry no supplier and are excluded here — their spend is still counted in the totals, and shows on Analyse as 'Unassigned supplier'. | G12: ='Invoices'!B69 | H12: =IF(AND(ISNUMBER(D12),ISNUMBER(G12)),IF(ABS(D12-G12)<0.05,"yes","NO"),"see note")
A13: Dashboard | B13: Quotes | C13: 29 | D13: 29 | E13: metrics.quoteCount | F13: Quotes, counted once each. A revised quote is stored as several records; they are resolved to one quote at its latest revision before counting. | G13: 29 | H13: =IF(AND(ISNUMBER(D13),ISNUMBER(G13)),IF(ABS(D13-G13)<0.05,"yes","NO"),"see note")
A14: Dashboard | B14: Purchase orders | C14: 39 | D14: 39 | E14: metrics.poCount | F14: Count of purchase-order records. | G14: 39 | H14: =IF(AND(ISNUMBER(D14),ISNUMBER(G14)),IF(ABS(D14-G14)<0.05,"yes","NO"),"see note")
A15: Analyse | B15: Invoiced spend | C15: — | E15: metrics.totalSpend | F15: Same figure and same rule as the Dashboard — the two screens read one source. | H15: n/a
A16: Analyse | B16: Savings realised | C16: £0 | D16: 0 | E16: metrics.savingsRealized | F16: Sum of realised savings on opportunity records. None have progressed, so this is a measured zero. | G16: 0 | H16: =IF(AND(ISNUMBER(D16),ISNUMBER(G16)),IF(ABS(D16-G16)<0.05,"yes","NO"),"see note")
A17: Analyse | B17: Deals | C17: 14 | D17: 14 | E17: metrics.dealCount | F17: Tracked deals — the same population the Pipeline screen lists, so the two cannot disagree. Uncommitted drafts are not counted here; they appear as draft analyses. | G17: 14 | H17: =IF(AND(ISNUMBER(D17),ISNUMBER(G17)),IF(ABS(D17-G17)<0.05,"yes","NO"),"see note")
A18: Analyse | B18: Top spend row 1 (Orbis Platform Sol) | C18: £1.1M | D18: 1116000 | E18: analyse.topRows[0].spend | F18: That supplier's invoices summed as billed. A currency symbol is printed only because this supplier billed in a single currency; a supplier billing in several shows a dash. | G18: =SUMIF(Invoices!$B$7:$B$57,"Orbis Platform Solutions Ltd",Invoices!G$7:G$57) | H18: =IF(AND(ISNUMBER(D18),ISNUMBER(G18)),IF(ABS(D18-G18)<0.05,"yes","NO"),"see note")
A19: Analyse | B19: …its share | C19: 59% | D19: 59 | E19: analyse.topRows[0].spendUsd | F19: The supplier's converted spend divided by the converted total of the table. Computed on the converted figures because shares of a mixed-currency sum are meaningless. | G19: =ROUND(SUMIF(Invoices!$B$7:$B$57,"Orbis Platform Solutions Ltd",Invoices!L$7:L$57)/SUM(Invoices!L7:L57)*100,0) | H19: =IF(AND(ISNUMBER(D19),ISNUMBER(G19)),IF(ABS(D19-G19)<0.05,"yes","NO"),"see note")
A20: Analyse | B20: Unassigned supplier | C20: — | E20: analyse.topRows | F20: The four invoices with no supplier, grouped and labelled rather than dropped, so the table still reconciles to the headline. A dash, not a figure, because these four span two currencies. | H20: n/a
A21: Pipeline | B21: Deals in flight | C21: 14 | D21: 14 | E21: deals[] | F21: The tracked deals listed on the screen. | G21: 14 | H21: =IF(AND(ISNUMBER(D21),ISNUMBER(G21)),IF(ABS(D21-G21)<0.05,"yes","NO"),"see note")
A22: Pipeline | B22: Invoiced total | C22: £189.3K | D22: 189280.61 | E22: deals.kpis.invoicedTotalUsd | F22: Invoice value across the tracked deals listed, converted — these deals are billed in several currencies, so there is no native total to show and the tile says so. It previously added them 1:1 and printed a sterling symbol. | G22: 189280.61 | H22: =IF(AND(ISNUMBER(D22),ISNUMBER(G22)),IF(ABS(D22-G22)<0.05,"yes","NO"),"see note")
A23: Pipeline | B23: Invoices not on this screen | C23: 26 invoices | D23: 26 | E23: deals.unattached.invoiceCount | F23: Invoices linked to no tracked deal. The screen totals spend by deal, so without this line their spend would simply be absent — and absent reads as non-existent. | G23: 26 | H23: =IF(AND(ISNUMBER(D23),ISNUMBER(G23)),IF(ABS(D23-G23)<0.05,"yes","NO"),"see note")
A24: Pipeline | B24: …their spend | C24: $2.3M | D24: 2279817.5 | E24: deals.unattached.spendUsd | F24: Those invoices converted on the live rate. Large because the biggest deal is an uncommitted draft, so it and its invoices sit outside the Pipeline entirely. | G24: =Deals!B27 | H24: =IF(AND(ISNUMBER(D24),ISNUMBER(G24)),IF(ABS(D24-G24)<0.05,"yes","NO"),"see note")
A25: Quotes | B25: Quote records | C25: 45 | D25: 45 | E25: quotes.total | F25: Every quote document held, revisions included. Labelled 'records' so it cannot be read as the number of quotes — the sub-line gives that. | G25: 45 | H25: =IF(AND(ISNUMBER(D25),ISNUMBER(G25)),IF(ABS(D25-G25)<0.05,"yes","NO"),"see note")
A26: Quotes | B26: Total quoted value | C26: $18.2M | D26: 18166895 | E26: quotes.summary.totalValueUsd | F26: Latest revision of each quote only. Summing every revision would add three rounds of one negotiation together. One quote is excluded entirely: its recorded net exceeds its tax-inclusive total, so the figure is withheld. Converted, because the corpus spans several currencies and a native sum could not carry a symbol. | G26: 18166895 | H26: =IF(AND(ISNUMBER(D26),ISNUMBER(G26)),IF(ABS(D26-G26)<0.05,"yes","NO"),"see note")
A27: Invoices | B27: Invoices | C27: 51 | D27: 51 | E27: invoices.total | F27: Count of invoice records. | G27: 51 | H27: =IF(AND(ISNUMBER(D27),ISNUMBER(G27)),IF(ABS(D27-G27)<0.05,"yes","NO"),"see note")
A28: Suppliers | B28: Total spend | C28: $2.5M | D28: 2455083.5 | E28: suppliers.summary.totalSpendUsd | F28: Converted invoiced spend that resolves to a named supplier. It sits below the Dashboard headline by exactly the spend on the four supplier-less invoices — the label says 'matched to a supplier' for that reason. | G28: ='Invoices'!B68 | H28: =IF(AND(ISNUMBER(D28),ISNUMBER(G28)),IF(ABS(D28-G28)<0.05,"yes","NO"),"see note")
A29: Suppliers | B29: With paid spend | C29: 19 | D29: 19 | E29: suppliers.summary.withSpend | F29: Suppliers whose invoices NET to more than zero. This can sit one below the Dashboard's 'invoiced' count, which counts anyone with an invoice at all: on this corpus one supplier has an invoice and a credit note that cancel exactly, so it is invoiced but has no net spend. Both figures are right; they answer different questions. | G29: 19 | H29: =IF(AND(ISNUMBER(D29),ISNUMBER(G29)),IF(ABS(D29-G29)<0.05,"yes","NO"),"see note")
B31: Rows marked 'n/a' are figures the screen deliberately does not print as a number — a dash where no honest single value exists, or a pre-formatted label. The reason is given in the calculation column.

Sheet Findings
A1: What the audit turned up
A2: Everything found across this audit, with the size of each and what was done. 'Fixed' items were corrected and are pinned by automated tests that fail if they regress.
A6: No. | B6: Status | C6: Severity | D6: What was wrong | E6: Size of it | F6: Why it happened | G6: What was done
A7: 1 | B7: FIXED | C7: High | D7: Quotes were counted and valued once per revision, not once per quote. | E7: 45 records are 29 quotes. Quoted value read £35.4M against £17.0M. | F7: Revisions are stored as separate rows and every query counted rows. BAFO rounds are the LOWEST of a series, so summing every round inflated a number that should be falling. | G7: Counts and totals resolve to the latest revision. The register still lists every revision and now labels the count 'Quote records' so it cannot be misread.
A8: 2 | B8: CONTAINED | C8: High | D8: One quote records a net larger than its tax-inclusive total, which cannot be true. | E8: ORB-Q-6612: net £3,335,591 against gross £1,315,200. Its tax line implies £1,096,000. | F8: Mis-read at extraction. The pipeline DID detect it, but filed it as one of 84 routine reconciliation warnings across 41 documents, so it was indistinguishable from ordinary discount and rounding gaps. | G8: Extraction now raises a distinct CRITICAL finding for the impossible case only — narrow by design, since blocking the general mismatch would stop a third of all documents. The screens withhold the figure and say why. The document still needs re-extracting: the true value must come from the page, not from our arithmetic.
A9: 3 | B9: FIXED | C9: High | D9: The Pipeline screen described a fraction of spend while appearing to describe all of it. | E9: 26 of 51 invoices reach no tracked deal. Pipeline covers £189,281 of a £1,922,469 corpus. | F9: The largest deal is an uncommitted draft, so it and its invoices sit outside the Pipeline. Spend absent from a by-deal roll-up looks identical to spend that does not exist. | G9: The screen now states the uncovered figure. Committing that draft, or explaining why it is still a draft, is a product decision rather than a code fix.
A10: 4 | B10: FIXED | C10: Medium | D10: The monthly chart did not add up to the headline figure printed above it. | E10: Chart $2,536,980 against a headline of $2,532,354. | F10: The chart converted on each record's stored rate; the headline used the live snapshot. | G10: Both now use the live snapshot and agree to the penny.
A11: 5 | B11: FIXED | C11: Medium | D11: The top-10 supplier share divided figures measured on two different rate bases. | E11: Published 98.6%; on a consistent basis 98.4%. | F11: The supplier ranking was never moved onto the live rate when the headline was. | G11: Ranking converts on the live rate. A test recomputes every supplier and fails if they diverge.
A12: 6 | B12: FIXED | C12: Medium | D12: Three spend figures added pounds and dollars together and printed a £ on the result. | E12: Analyse's spend table read £1,922,469 for £1,824,950 + $97,519. The Analyse and trend charts did the same. | F12: Those queries summed as-billed amounts with no conversion — the places the safeguards used elsewhere had not reached. | G12: All three convert before summing. A symbol is printed only for a supplier that billed in one currency; otherwise a dash.
A13: 7 | B13: FIXED | C13: Medium | D13: Three screens gave three different answers to 'how many deals'. | E13: Analyse said 15, Pipeline listed 14, the Home summary card said 15, the nav badge said 15. | F13: Each counted a different population; the Home card and badge read a view covering every deal including drafts. | G13: All four now count tracked deals — the population the Pipeline screen lists.
A14: 8 | B14: FIXED | C14: Low | D14: Four invoices carry no supplier and their spend belonged to no row. | E14: 4 of 51 invoices, £58,190 as billed. | F14: The supplier could not be resolved at extraction. | G14: Grouped and labelled 'Unassigned supplier' so the table still reconciles to the headline. Resolving the real supplier remains a data task.
A15: 9 | B15: MITIGATED | C15: Medium | D15: The same currency is stored against different rates across records. | E15: Sterling invoices carry stored rates from 1.27 to 1.3445 — a 5.9% spread. | F15: The rate is stamped on each record at extraction, so records extracted at different times keep different rates. | G15: No displayed figure depends on the stored rate any more; everything converts at read time from one table. The data is still inconsistent and re-stamping it remains worthwhile.
A16: 10 | B16: BY DESIGN | C16: Low | D16: The Analyse spend chart does not total the Invoiced-spend KPI beside it. | E16: The chart covers the selected range (FY26 by default); the KPI covers the whole corpus. | F16: The chart has a range selector and the KPI does not. | G16: Left as is — this is the range selector working. Worth labelling the chart with its range so the difference is obvious.
A17: 11 | B17: NO DATA YET | C17: Low | D17: Savings figures and the Negotiations screen are empty. | E17: Both savings KPIs show £0; Negotiations has no rows. | F17: No opportunity records exist yet. The zero is measured, not assumed. | G17: Nothing to fix: the screens are correct and will populate when the detectors run. Worth saying so on screen.
A18: 12 | B18: PRODUCT CALL | C18: Low | D18: Two screens show demo content, and one is part demo. | E18: Demand intake and Third-party risk are examples; Requirements is part real, part scripted. | F18: No ingestion built yet. Each already carries an on-screen notice. | G18: A decision, not a defect: build the ingestion or hide them for customer use. Inventing data is not an option.
B20: 7 fixed and verified live · 1 contained (bad value no longer published; document still needs re-extracting) · 1 mitigated · 3 are not code defects

Sheet Invoices
A1: Invoice records — the source behind every spend figure on screen
A2: Every invoice held, exactly as stored. The rate is looked up from the 'FX rates' sheet by formula, and the two conversion columns are formulas over it. The totals at the bottom are what the screens' spend figures are built from — change a row and they move.
A6: Invoice | B6: Supplier | C6: Supplier ID | D6: PO | E6: PO found | F6: Ccy | G6: Net amount | H6: Gross (incl tax) | I6: Tax | J6: Rate stored | K6: Rate live | L6: Net in USD (live) | M6: Net in USD (stored) | N6: Stored USD col | O6: Date
A7: 123456/22 | B7: FASHION QUEEN | C7: SUP-FashionQueen | D7: 123456/22 | E7: yes | F7: USD | G7: 3565 | H7: 3729.35 | J7: 1 | K7: =IFERROR(VLOOKUP(F7,'FX rates'!$A$7:$B$40,2,FALSE),"") | L7: =IF(OR(G7="",K7="",K7=0),"",G7/K7) | M7: =IF(OR(G7="",J7=""),"",G7*J7) | N7: 3729.35 | O7: 2022-09-22
A8: 132548 | B8: Duncan LLC | C8: SUP-DuncanLlc | D8: 526702 | E8: yes | F8: GBP | G8: 2131.05 | H8: 2557.26 | I8: 426.21 | J8: 1.27 | K8: =IFERROR(VLOOKUP(F8,'FX rates'!$A$7:$B$40,2,FALSE),"") | L8: =IF(OR(G8="",K8="",K8=0),"",G8/K8) | M8: =IF(OR(G8="",J8=""),"",G8*J8) | N8: 3247.72 | O8: 2024-10-01
A9: 132666 | B9: Duncan LLC | C9: SUP-DuncanLlc | D9: 526702 | E9: yes | F9: GBP | G9: 2399.7 | H9: 2879.64 | I9: 479.94 | J9: 1.27 | K9: =IFERROR(VLOOKUP(F9,'FX rates'!$A$7:$B$40,2,FALSE),"") | L9: =IF(OR(G9="",K9="",K9=0),"",G9/K9) | M9: =IF(OR(G9="",J9=""),"",G9*J9) | N9: 3657.14 | O9: 2024-01-10
A10: 148769 | B10: Perry Ltd | C10: SUP-PerryLtd | D10: 526689 | E10: yes | F10: GBP | G10: 2826.65 | H10: 3391.98 | I10: 565.33 | J10: 1.27 | K10: =IFERROR(VLOOKUP(F10,'FX rates'!$A$7:$B$40,2,FALSE),"") | L10: =IF(OR(G10="",K10="",K10=0),"",G10/K10) | M10: =IF(OR(G10="",J10=""),"",G10*J10) | N10: 4307.81 | O10: 2024-09-27
A11: 2025-290 | B11: Eleanor Price Creative Studio | C11: SUP-EleanorPriceCreativeStudio | D11: 389948 | E11: yes | F11: GBP | G11: 1200 | H11: 1440 | I11: 240 | J11: 1.27 | K11: =IFERROR(VLOOKUP(F11,'FX rates'!$A$7:$B$40,2,FALSE),"") | L11: =IF(OR(G11="",K11="",K11=0),"",G11/K11) | M11: =IF(OR(G11="",J11=""),"",G11*J11) | N11: 1828.8 | O11: 2020-04-01
A12: 2025-291 | B12: Eleanor Price Creative Studio | C12: SUP-EleanorPriceCreativeStudio | D12: 389948 | E12: yes | F12: GBP | G12: 1200 | H12: 1440 | I12: 240 | J12: 1.27 | K12: =IFERROR(VLOOKUP(F12,'FX rates'!$A$7:$B$40,2,FALSE),"") | L12: =IF(OR(G12="",K12="",K12=0),"",G12/K12) | M12: =IF(OR(G12="",J12=""),"",G12*J12) | N12: 1828.8 | O12: 2020-05-01
A13: 2025-292 | B13: Eleanor Price Creative Studio | C13: SUP-EleanorPriceCreativeStudio | D13: 389948 | E13: yes | F13: GBP | G13: 1200 | H13: 1440 | I13: 240 | J13: 1.27 | K13: =IFERROR(VLOOKUP(F13,'FX rates'!$A$7:$B$40,2,FALSE),"") | L13: =IF(OR(G13="",K13="",K13=0),"",G13/K13) | M13: =IF(OR(G13="",J13=""),"",G13*J13) | N13: 1828.8 | O13: 2020-06-01
A14: 4759275 | B14: NEXASPARK | C14: SUP-Nexaspark | D14: 506789 | E14: yes | F14: GBP | G14: 10000 | H14: 12000 | I14: 2000 | J14: 1.27 | K14: =IFERROR(VLOOKUP(F14,'FX rates'!$A$7:$B$40,2,FALSE),"") | L14: =IF(OR(G14="",K14="",K14=0),"",G14/K14) | M14: =IF(OR(G14="",J14=""),"",G14*J14) | N14: 15240 | O14: 2025-06-12
A15: 4759276 | B15: NEXASPARK | C15: SUP-Nexaspark | D15: 506789 | E15: yes | F15: GBP | G15: 15000 | H15: 18000 | I15: 3000 | J15: 1.27 | K15: =IFERROR(VLOOKUP(F15,'FX rates'!$A$7:$B$40,2,FALSE),"") | L15: =IF(OR(G15="",K15="",K15=0),"",G15/K15) | M15: =IF(OR(G15="",J15=""),"",G15*J15) | N15: 22860 | O15: 2025-12-12
A16: DHA-2025-143 | B16: Design House Agency | C16: SUP-DesignHouseAgency | D16: 438295 | E16: yes | F16: GBP | G16: 2000 | H16: 2400 | I16: 400 | J16: 1.27 | K16: =IFERROR(VLOOKUP(F16,'FX rates'!$A$7:$B$40,2,FALSE),"") | L16: =IF(OR(G16="",K16="",K16=0),"",G16/K16) | M16: =IF(OR(G16="",J16=""),"",G16*J16) | N16: 3048 | O16: 2022-07-01
A17: DHA-2025-144 | B17: Design House Agency | C17: SUP-DesignHouseAgency | D17: 438295 | E17: yes | F17: GBP | G17: 2000 | H17: 2400 | I17: 400 | J17: 1.27 | K17: =IFERROR(VLOOKUP(F17,'FX rates'!$A$7:$B$40,2,FALSE),"") | L17: =IF(OR(G17="",K17="",K17=0),"",G17/K17) | M17: =IF(OR(G17="",J17=""),"",G17*J17) | N17: 3048 | O17: 2022-08-01
A18: DHA-2025-145 | B18: Design House Agency | C18: SUP-DesignHouseAgency | D18: 438295 | E18: yes | F18: GBP | G18: 2000 | H18: 2400 | I18: 400 | J18: 1.27 | K18: =IFERROR(VLOOKUP(F18,'FX rates'!$A$7:$B$40,2,FALSE),"") | L18: =IF(OR(G18="",K18="",K18=0),"",G18/K18) | M18: =IF(OR(G18="",J18=""),"",G18*J18) | N18: 3048 | O18: 2022-09-01
A19: INV-1011 | B19: CREATIVE DESIGN AGENCY | C19: SUP-CreativeDesignAgency | D19: — | E19: no | F19: USD | G19: 23680 | H19: 24980 | J19: 1 | K19: =IFERROR(VLOOKUP(F19,'FX rates'!$A$7:$B$40,2,FALSE),"") | L19: =IF(OR(G19="",K19="",K19=0),"",G19/K19) | M19: =IF(OR(G19="",J19=""),"",G19*J19) | N19: 24980 | O19: 2022-01-22
A20: INV-154586 | B20: (no supplier on record) | C20: — | D20: 154586 | E20: yes | F20: USD | G20: 1094 | H20: 1212.6 | I20: 109.4 | J20: 1 | K20: =IFERROR(VLOOKUP(F20,'FX rates'!$A$7:$B$40,2,FALSE),"") | L20: =IF(OR(G20="",K20="",K20=0),"",G20/K20) | M20: =IF(OR(G20="",J20=""),"",G20*J20) | N20: 1212.6 | O20: 2022-05-02
A21: INV-2023010B | B21: Coffee Bliss Suppliers | C21: SUP-CoffeeBlissSuppliers | D21: PO2023010 | E21: yes | F21: USD | G21: 5825 | H21: 6232.75 | I21: 407.75 | J21: 1 | K21: =IFERROR(VLOOKUP(F21,'FX rates'!$A$7:$B$40,2,FALSE),"") | L21: =IF(OR(G21="",K21="",K21=0),"",G21/K21) | M21: =IF(OR(G21="",J21=""),"",G21*J21) | N21: 6232.75 | O21: 2023-03-05
A22: INV-2023010-X2 | B22: Coffee Bliss Suppliers | C22: SUP-CoffeeBlissSuppliers | D22: PO2023010 | E22: yes | F22: USD | G22: 5825 | H22: 6232.75 | I22: 407.75 | J22: 1 | K22: =IFERROR(VLOOKUP(F22,'FX rates'!$A$7:$B$40,2,FALSE),"") | L22: =IF(OR(G22="",K22="",K22=0),"",G22/K22) | M22: =IF(OR(G22="",J22=""),"",G22*J22) | N22: 6232.75 | O22: 2023-04-05
A23: INV-2023010-X3 | B23: Coffee Bliss Suppliers | C23: SUP-CoffeeBlissSuppliers | D23: PO2023010 | E23: yes | F23: USD | G23: 5825 | H23: 6432.75 | I23: 407.75 | J23: 1 | K23: =IFERROR(VLOOKUP(F23,'FX rates'!$A$7:$B$40,2,FALSE),"") | L23: =IF(OR(G23="",K23="",K23=0),"",G23/K23) | M23: =IF(OR(G23="",J23=""),"",G23*J23) | N23: 6432.75 | O23: 2023-03-05
A24: INV-2023010-X4 | B24: Coffee Bliss Suppliers | C24: SUP-CoffeeBlissSuppliers | D24: PO2023010 | E24: yes | F24: USD | G24: 7825 | H24: 8372.75 | I24: 547.75 | J24: 1 | K24: =IFERROR(VLOOKUP(F24,'FX rates'!$A$7:$B$40,2,FALSE),"") | L24: =IF(OR(G24="",K24="",K24=0),"",G24/K24) | M24: =IF(OR(G24="",J24=""),"",G24*J24) | N24: 8372.75 | O24: 2023-03-05
A25: INV-2023010-X5 | B25: Coffee Bliss Suppliers | C25: SUP-CoffeeBlissSuppliers | D25: PO2023010 | E25: yes | F25: USD | G25: 6425 | H25: 6874.75 | I25: 449.75 | J25: 1 | K25: =IFERROR(VLOOKUP(F25,'FX rates'!$A$7:$B$40,2,FALSE),"") | L25: =IF(OR(G25="",K25="",K25=0),"",G25/K25) | M25: =IF(OR(G25="",J25=""),"",G25*J25) | N25: 6874.75 | O25: 2023-03-05
A26: INV-2023010-X6A | B26: Coffee Bliss Suppliers | C26: SUP-CoffeeBlissSuppliers | D26: PO2023010 | E26: yes | F26: USD | G26: 1125 | H26: 1203.75 | I26: 78.75 | J26: 1 | K26: =IFERROR(VLOOKUP(F26,'FX rates'!$A$7:$B$40,2,FALSE),"") | L26: =IF(OR(G26="",K26="",K26=0),"",G26/K26) | M26: =IF(OR(G26="",J26=""),"",G26*J26) | N26: 1203.75 | O26: 2023-03-05
A27: INV-2023010-X6B | B27: Coffee Bliss Suppliers | C27: SUP-CoffeeBlissSuppliers | D27: PO2023010 | E27: yes | F27: USD | G27: 4700 | H27: 5029 | I27: 329 | J27: 1 | K27: =IFERROR(VLOOKUP(F27,'FX rates'!$A$7:$B$40,2,FALSE),"") | L27: =IF(OR(G27="",K27="",K27=0),"",G27/K27) | M27: =IF(OR(G27="",J27=""),"",G27*J27) | N27: 5029 | O27: 2023-03-05
A28: INV-2026-01602 | B28: PeopleFirst HR Solutions Ltd | C28: SUP-PeoplefirstHrSolutionsLtd | D28: PO5206556 | E28: yes | F28: GBP | G28: 100000 | H28: 120000 | I28: 20000 | J28: 1.27 | K28: =IFERROR(VLOOKUP(F28,'FX rates'!$A$7:$B$40,2,FALSE),"") | L28: =IF(OR(G28="",K28="",K28=0),"",G28/K28) | M28: =IF(OR(G28="",J28=""),"",G28*J28) | N28: 152400 | O28: 2025-10-10
A29: INV25-021-75 | B29: InfoTech | C29: SUP-Infotech | D29: — | E29: no | F29: GBP | G29: 1200 | H29: 1440 | I29: 240 | J29: 1.27 | K29: =IFERROR(VLOOKUP(F29,'FX rates'!$A$7:$B$40,2,FALSE),"") | L29: =IF(OR(G29="",K29="",K29=0),"",G29/K29) | M29: =IF(OR(G29="",J29=""),"",G29*J29) | N29: 1828.8 | O29: 2019-01-20
A30: INV25-021-76 | B30: InfoTech | C30: SUP-Infotech | D30: — | E30: no | F30: GBP | G30: 1200 | H30: 1440 | I30: 240 | J30: 1.27 | K30: =IFERROR(VLOOKUP(F30,'FX rates'!$A$7:$B$40,2,FALSE),"") | L30: =IF(OR(G30="",K30="",K30=0),"",G30/K30) | M30: =IF(OR(G30="",J30=""),"",G30*J30) | N30: 1828.8 | O30: 2019-02-20
A31: INV-25-050 | B31: AUARIUS MARKETING | C31: SUP-AuariusMarketing | D31: — | E31: no | F31: GBP | G31: 5000 | H31: 6000 | I31: 1000 | J31: 1.27 | K31: =IFERROR(VLOOKUP(F31,'FX rates'!$A$7:$B$40,2,FALSE),"") | L31: =IF(OR(G31="",K31="",K31=0),"",G31/K31) | M31: =IF(OR(G31="",J31=""),"",G31*J31) | N31: 7620 | O31: 2025-07-22
... A49: INV-981204-F2 | B49: Veruca Organic Nuts | C49: SUP-VerucaOrganicNuts | D49: GB-001 | E49: yes | F49: GBP | G49: 45 | H49: 54 | I49: 9 | J49: 1.27 | K49: =IFERROR(VLOOKUP(F49,'FX rates'!$A$7:$B$40,2,FALSE),"") | L49: =IF(OR(G49="",K49="",K49=0),"",G49/K49) | M49: =IF(OR(G49="",J49=""),"",G49*J49) | N49: 68.58 | O49: 2019-01-29
A50: INV-B-23476 | B50: INTERIOR DESIGN, Inc. | C50: SUP-InteriorDesignInc | D50: B-23476 | E50: yes | F50: USD | G50: 3950 | H50: 3950 | J50: 1 | K50: =IFERROR(VLOOKUP(F50,'FX rates'!$A$7:$B$40,2,FALSE),"") | L50: =IF(OR(G50="",K50="",K50=0),"",G50/K50) | M50: =IF(OR(G50="",J50=""),"",G50*J50) | N50: 3950 | O50: 2024-08-20
A51: MCG-INV-2024-0377 | B51: Meridian Consulting Group Ltd | C51: SUP-MeridianConsultingGroupLtd | D51: PO-2024-0114 | E51: yes | F51: GBP | G51: 230765 | H51: 276918 | I51: 46153 | J51: 1.3445 | K51: =IFERROR(VLOOKUP(F51,'FX rates'!$A$7:$B$40,2,FALSE),"") | L51: =IF(OR(G51="",K51="",K51=0),"",G51/K51) | M51: =IF(OR(G51="",J51=""),"",G51*J51) | N51: 372310.7 | O51: 2024-04-30
A52: MCG-INV-2024-0389 | B52: Meridian Consulting Group Ltd | C52: SUP-MeridianConsultingGroupLtd | D52: PO-2024-0114 | E52: yes | F52: GBP | G52: 230689 | H52: 276826.8 | I52: 46137.8 | J52: 1.3445 | K52: =IFERROR(VLOOKUP(F52,'FX rates'!$A$7:$B$40,2,FALSE),"") | L52: =IF(OR(G52="",K52="",K52=0),"",G52/K52) | M52: =IF(OR(G52="",J52=""),"",G52*J52) | N52: 372188.09 | O52: 2024-05-31
A53: ORB-INV-9901 | B53: Orbis Platform Solutions Ltd | C53: SUP-OrbisPlatformSolutionsLtd | D53: PO-2024-0145 | E53: yes | F53: GBP | G53: 1048000 | H53: 1257600 | I53: 209600 | J53: 1.3445 | K53: =IFERROR(VLOOKUP(F53,'FX rates'!$A$7:$B$40,2,FALSE),"") | L53: =IF(OR(G53="",K53="",K53=0),"",G53/K53) | M53: =IF(OR(G53="",J53=""),"",G53*J53) | N53: 1690818 | O53: 2024-05-01
A54: ORB-INV-9920 | B54: Orbis Platform Solutions Ltd | C54: SUP-OrbisPlatformSolutionsLtd | D54: PO-2024-0145 | E54: yes | F54: GBP | G54: 68000 | H54: 81600 | I54: 13600 | J54: 1.3445 | K54: =IFERROR(VLOOKUP(F54,'FX rates'!$A$7:$B$40,2,FALSE),"") | L54: =IF(OR(G54="",K54="",K54=0),"",G54/K54) | M54: =IF(OR(G54="",J54=""),"",G54*J54) | N54: 109709.57 | O54: 2024-06-15
A55: SWF-INV-7741 | B55: (no supplier on record) | C55: — | D55: PO-2024-0091 | E55: yes | F55: GBP | G55: 18083.67 | H55: 21700.4 | I55: 3616.73 | J55: 1.3445 | K55: =IFERROR(VLOOKUP(F55,'FX rates'!$A$7:$B$40,2,FALSE),"") | L55: =IF(OR(G55="",K55="",K55=0),"",G55/K55) | M55: =IF(OR(G55="",J55=""),"",G55*J55) | N55: 29175.75 | O55: 2024-05-31
A56: SWF-INV-7763 | B56: (no supplier on record) | C56: — | D56: PO-2024-0091 | E56: yes | F56: GBP | G56: 19065.23 | H56: 22878.28 | I56: 3813.05 | J56: 1.3445 | K56: =IFERROR(VLOOKUP(F56,'FX rates'!$A$7:$B$40,2,FALSE),"") | L56: =IF(OR(G56="",K56="",K56=0),"",G56/K56) | M56: =IF(OR(G56="",J56=""),"",G56*J56) | N56: 30759.39 | O56: 2024-06-30
A57: SWF-INV-7785 | B57: (no supplier on record) | C57: — | D57: PO-2024-0091 | E57: yes | F57: GBP | G57: 19946.92 | H57: 23936.3 | I57: 3989.38 | J57: 1.3445 | K57: =IFERROR(VLOOKUP(F57,'FX rates'!$A$7:$B$40,2,FALSE),"") | L57: =IF(OR(G57="",K57="",K57=0),"",G57/K57) | M57: =IF(OR(G57="",J57=""),"",G57*J57) | N57: 32181.88 | O57: 2024-07-31
A59: TOTAL — all invoices | G59: =SUM(G7:G57) | H59: =SUM(H7:H57) | I59: =SUM(I7:I57) | L59: =SUM(L7:L57) | M59: =SUM(M7:M57) | N59: =SUM(N7:N57)
A61: Blocks the screens quote directly
A62: Figure | B62: Value | C62: How it is built
...

Sheet FX rates
A1: Exchange-rate snapshot
A2: One snapshot, used by every conversion in this workbook and by the product itself. Rates are USD-quoted: the number is how many units of that currency equal one US dollar, so converting INTO dollars divides by it.
A5: Snapshot taken: 2026-07-27T14:26:47.300129+00:00
A6: Currency | B6: Rate (per 1 USD) | C6: 1 unit = USD | D6: Used for
A7: EUR | B7: 0.877986 | C7: =IF(B7=0,"",1/B7) | D7: Every spend figure, chart and share on every screen
A8: GBP | B8: 0.749517 | C8: =IF(B8=0,"",1/B8) | D8: Every spend figure, chart and share on every screen
A9: USD | B9: 1 | C9: =IF(B9=0,"",1/B9) | D9: Every spend figure, chart and share on every screen

Sheet Spend by month
A1: The monthly spend chart
A2: The series behind the Dashboard chart, converted on the live rate — the same basis as the headline KPI above it, so the chart adds up to the headline exactly.
A6: Month | B6: Charted value | C6: Running total
A7: January 2019 | B7: 2895.1978 | C7: =SUM($B$7:B7)
A8: February 2019 | B8: 1801.1599 | C8: =SUM($B$7:B8)
A9: July 2019 | B9: 11117.827 | C9: =SUM($B$7:B9)
A10: August 2019 | B10: 11117.827 | C10: =SUM($B$7:B10)
A11: September 2019 | B11: 11117.827 | C11: =SUM($B$7:B11)
A12: April 2020 | B12: 1601.0311 | C12: =SUM($B$7:B12)
A13: May 2020 | B13: 1601.0311 | C13: =SUM($B$7:B13)
A14: June 2020 | B14: 1601.0311 | C14: =SUM($B$7:B14)
A15: January 2022 | B15: 23680 | C15: =SUM($B$7:B15)
A16: March 2022 | B16: 27680 | C16: =SUM($B$7:B16)
A17: May 2022 | B17: 1094 | C17: =SUM($B$7:B17)
A18: July 2022 | B18: 2668.3851 | C18: =SUM($B$7:B18)
... A40: December 2025 | B40: 20012.888 | C40: =SUM($B$7:B40)
A42: Chart total | B42: =SUM(B7:B40)
A43: Headline KPI | B43: =SUM(Invoices!L7:L57)
A44: Difference | B44: =B42-B43

Sheet Quotes
A1: Quote records, grouped by the quote they belong to
A2: Revised quotes are separate records ('(V2)', '(V3 (BAFO))'). The register lists them all — each is a real document — but counts and totals resolve to the latest revision of each quote. Note the BAFO rounds are the LOWEST of their series, so summing every round inflates a figure that should be falling.
A6: Quote record | B6: Underlying quote | C6: Revision | D6: Supplier | E6: Net amount | F6: Gross (incl tax) | G6: Check
A7: 01475 | B7: 01475 | C7: V1 | D7: SUP-EleanorPriceCreativeStudio | E7: 3600 | F7: 4320 | G7: =IF(E7>F7,"NET > GROSS — withheld on screen","ok")
A8: 102494 | B8: 102494 | C8: V1 | D8: SUP-DixonReynoldsAndSolomon | E8: 638.6 | F8: 766.32 | G8: =IF(E8>F8,"NET > GROSS — withheld on screen","ok")
A9: 10253 | B9: 10253 | C9: V1 | D9: SUP-DixonReynoldsAndSolomon | E9: 1318.4 | F9: 1582.08 | G9: =IF(E9>F9,"NET > GROSS — withheld on screen","ok")
A10: 104680 | B10: 104680 | C10: V1 | D10: SUP-GomezGoodAndCross | E10: 1169.58 | F10: 1403.5 | G10: =IF(E10>F10,"NET > GROSS — withheld on screen","ok")
A11: 104683 | B11: 104683 | C11: V1 | D11: SUP-GomezGoodAndCross | E11: 647.17 | F11: 776.6 | G11: =IF(E11>F11,"NET > GROSS — withheld on screen","ok")
A12: 104837 | B12: 104837 | C12: V1 | D12: SUP-GomezGoodAndCross | E12: 1150.46 | F12: 1380.55 | G12: =IF(E12>F12,"NET > GROSS — withheld on screen","ok")
A13: 128234 | B13: 128234 | C13: V1 | D13: SUP-DuncanLlc | E13: 2131.05 | F13: 2557.26 | G13: =IF(E13>F13,"NET > GROSS — withheld on screen","ok")
A14: 136586 | B14: 136586 | C14: V1 | D14: SUP-PerryLtd | E14: 2826.65 | F14: 3391.98 | G14: =IF(E14>F14,"NET > GROSS — withheld on screen","ok")
A15: 2026-00487 | B15: 2026-00487 | C15: V1 | D15: SUP-SupplyxLtd | E15: 66910 | F15: 80292 | G15: =IF(E15>F15,"NET > GROSS — withheld on screen","ok")
A16: 2026-01521 | B16: 2026-01521 | C16: V1 | D16: SUP-PeoplefirstHrSolutionsLtd | E16: 100000 | F16: 120000 | G16: =IF(E16>F16,"NET > GROSS — withheld on screen","ok")
A17: 25-032 | B17: 25-032 | C17: V1 | D17: SUP-AuariusMarketing | E17: 60000 | F17: 72000 | G17: =IF(E17>F17,"NET > GROSS — withheld on screen","ok")
A18: 25-304-34 | B18: 25-304-34 | C18: V1 | D18: SUP-Infotech | E18: 7200 | F18: 8640 | G18: =IF(E18>F18,"NET > GROSS — withheld on screen","ok")
... A42: POM-2024-220 (V2) | B42: POM-2024-220 | C42: V2 | D42: SUP-PrimeopsManagedSolutionsLtd | E42: 1344760 | F42: 1613712 | G42: =IF(E42>F42,"NET > GROSS — withheld on screen","ok")
A43: SDP-Q-44120 (V1) | B43: SDP-Q-44120 | C43: V1 | E43: 207656 | F43: 249187.2 | G43: =IF(E43>F43,"NET > GROSS — withheld on screen","ok")
A44: SDP-Q-44120 (V2) | B44: SDP-Q-44120 | C44: V2 | E44: 202836 | F44: 243403.2 | G44: =IF(E44>F44,"NET > GROSS — withheld on screen","ok")
A45: SDP-Q-44120 (V3 (BAFO)) | B45: SDP-Q-44120 | C45: V3 | E45: 199806 | F45: 239767.2 | G45: =IF(E45>F45,"NET > GROSS — withheld on screen","ok")
A46: SYN-MSA-3320 | B46: SYN-MSA-3320 | C46: V1 | D46: SUP-SynapseItServicesLtd | E46: 1259640 | F46: 1511568 | G46: =IF(E46>F46,"NET > GROSS — withheld on screen","ok")
A47: SYN-MSA-3320 (V2) | B47: SYN-MSA-3320 | C47: V2 | D47: SUP-SynapseItServicesLtd | E47: 1291640 | F47: 1549968 | G47: =IF(E47>F47,"NET > GROSS — withheld on screen","ok")
A48: VAP-2024-0091 | B48: VAP-2024-0091 | C48: V1 | D48: SUP-VantageAdvisoryPartnersLlp | E48: 2030070.5 | F48: 2436084.6 | G48: =IF(E48>F48,"NET > GROSS — withheld on screen","ok")
A49: VAP-2024-0091 (V2) | B49: VAP-2024-0091 | C49: V2 | D49: SUP-VantageAdvisoryPartnersLlp | E49: 2147402 | F49: 2576882.4 | G49: =IF(E49>F49,"NET > GROSS — withheld on screen","ok")
A50: WSG100024 | B50: WSG100024 | C50: V1 | D50: SUP-DellWorkspaceSolutionsLtd | E50: 111975 | F50: 134370 | G50: =IF(E50>F50,"NET > GROSS — withheld on screen","ok")
A51: WSG100025 | B51: WSG100025 | C51: V1 | D51: SUP-DellWorkspaceSolutionsLtd | E51: 111975 | F51: 134370 | G51: =IF(E51>F51,"NET > GROSS — withheld on screen","ok")
A53: Every record added together (the old behaviour) | C53: 45 | E53: 35443342
A54: Latest revision of each quote | C54: 29 | E54: 16951987
A55: …excluding the withheld record — what the screen shows | C55: 29 | E55: 13616396

Sheet Deals
A1: Deal roll-ups, and the spend that reaches no deal
A2: Deal totals against the invoices behind them. The reconciliation at the bottom accounts for every invoice, including those on no tracked deal at all.
A6: Deal | B6: Name | C6: Supplier | D6: Quotes | E6: POs | F6: Invoices | G6: Quote total | H6: PO total | I6: Invoice total
A7: ANALYSISSET_19072620260719339 | B7: Analysis Set_190726 (draft — not on Pipeline) | C7: Synapse IT Services Ltd | D7: 28 | E7: 5 | F7: 7 | G7: 34840800 | H7: 6551667.7 | I7: 1634549.8
A8: AQUARIUSSET-1E2E20260716237 | B8: Aquarius set-1 E2E | C8: Aquarius Marketing Ltd | D8: 1 | E8: 1 | F8: 3 | G8: 60000 | H8: 60000 | I8: 15000
A9: DEALV2-5206556 | B9: PeopleFirst HR Solutions Ltd — PO 5206556 | C9: PeopleFirst HR Solutions Ltd | D9: 1 | E9: 1 | F9: 1 | G9: 100000 | H9: 100000 | I9: 100000
A10: DESIGNHOUSEAGENCYSET-3E2E20260716249 | B10: Design House Agency set-3 E2E | C10: Design House Agency | D10: 1 | E10: 1 | F10: 3 | G10: 6000 | H10: 6000 | I10: 6000
A11: DIXON,REYNOLDSETCSET-4E2E20260716254 | B11: Dixon, Reynolds Etc set-4 E2E | C11: Dixon, Reynolds and Solomon | D11: 1 | E11: 1 | F11: 1 | G11: 1318.4 | H11: 1318.4 | I11: 1318.4
A12: DIXON,REYNOLDSETCSET-5E2E20260716257 | B12: Dixon, Reynolds Etc set-5 E2E | C12: Dixon, Reynolds and Solomon | D12: 1 | E12: 1 | F12: 1 | G12: 638.6 | H12: 638.6 | I12: 638.6
A13: DUNCANSET-6E2E20260716260 | B13: Duncan set-6 E2E | C13: Duncan LLC | D13: 1 | E13: 1 | F13: 2 | G13: 2131.05 | H13: 2131.05 | I13: 4530.75
A14: ELEANORPRICESET-7E2E20260716264 | B14: Eleanor Price set-7 E2E | C14: Eleanor Price Creative Studio | D14: 1 | E14: 1 | F14: 3 | G14: 3600 | H14: 3600 | I14: 3600
A15: GOMEZ,GOODETC5SET-10E2E20260716275 | B15: Gomez, Good Etc5 set-10 E2E | C15: Gomez, Good and Cross Trading Ltd | D15: 1 | E15: 1 | F15: 1 | G15: 1169.58 | H15: 1169.58 | I15: 1169.58
A16: GOMEZ,GOODETC5SET-9E2E20260716272 | B16: Gomez, Good Etc5 set-9 E2E | C16: Gomez, Good and Cross Trading Ltd | D16: 1 | E16: 1 | F16: 1 | G16: 1150.46 | H16: 1150.46 | I16: 1150.46
A17: GOMEZ,GOODETCSET-8E2E20260716269 | B17: Gomez, Good Etc set-8 E2E | C17: Gomez, Good and Cross Trading Ltd | D17: 1 | E17: 1 | F17: 1 | G17: 647.17 | H17: 647.17 | I17: 647.17
A18: INFOTECHSET-11E2E20260716278 | B18: Infotech set-11 E2E | C18: InfoTech Consulting | D18: 1 | E18: 1 | F18: 2 | G18: 7200 | H18: 7200 | I18: 2400
... A21: PERRYSET-13E2E20260716286 | B21: Perry set-13 E2E | C21: Perry Ltd | D21: 1 | E21: 1 | F21: 1 | G21: 2826.65 | H21: 2826.65 | I21: 2826.65
A22: All deals (incl. drafts) | D22: =SUM(D7:D21) | E22: =SUM(E7:E21) | F22: =SUM(F7:F21) | G22: =SUM(G7:G21) | H22: =SUM(H7:H21) | I22: =SUM(I7:I21)
A24: What the Pipeline screen covers
A25: Deals listed on Pipeline | B25: 14 | C25: Tracked deals only
A26: Invoices reaching no tracked deal | B26: 26 | C26: out of 51
A27: …their converted spend | B27: 2279817.5 | C27: Now stated on the screen rather than omitted
A28: Why so large | C28: The single biggest deal is an uncommitted draft, so it and its invoices sit outside the Pipeline

Sheet Screen coverage
A1: Which screens are backed by real data
A2: From the product's own coverage map. Screens marked 'Examples only' show content that came from no uploaded document — worth knowing before a customer sees them.
A6: Screen | B6: Status | C6: What that means
A7: Dashboard | B7: Real data | C7: Spend, counts and the monthly chart from extracted documents. Verified on the 'On screen' sheet.
A8: Analyse | B8: Real data | C8: Same source as the Dashboard. Its spend chart is range-limited — see Findings.
A9: Pipeline | B9: Real data | C9: 14 tracked deals, plus an explicit line for spend on no tracked deal.
A10: Quotes | B10: Real data | C10: Every quote record, with totals counted once per quote.
A11: Invoices | B11: Real data | C11: Invoice records as extracted.
A12: Purchase orders | B12: Real data | C12: PO records as extracted.
A13: Suppliers | B13: Real data | C13: Supplier master plus invoiced spend matched to a named supplier.
A14: Discrepancies | B14: Real data | C14: 1077 findings raised against extracted documents.
A15: Audit logs | B15: Real data | C15: The agent event log.
A16: Alerts | B16: Real data | C16: Derived from recent agent events.
A17: Compliance | B17: Real data | C17: Portfolio compliance findings.
... A25: Third-party risk | B25: Examples only | C25: The risk profiles are examples, not assessments of real suppliers.
