Workbook

Sheet GUIDE – Start Here
A1: BENCHMARK PRICING WORKBOOK – GUIDE FOR ALL USERS
A2: WHAT IS THIS WORKBOOK FOR?
A3: This workbook calculates a fair benchmark unit price for each item or service you are buying, then tells you whether the supplier's quote is above or below that benchmark. The benchmark is built from real historical prices drawn from two sources: • Internal data – your organisation's own past purchase orders, invoices, and quotes • External database – prices imported from an external spend warehouse or market data system Combining both sources gives you a richer, more reliable picture of fair market price.
A4: HOW THE BENCHMARK IS CALCULATED (plain English)
A5: Step 1 – Matching: The workbook finds all historical prices for the same item, unit of measure, and currency. Step 2 – Aggregation: It averages those prices (simple, weighted, or median – set in Benchmark Settings). Weighted average is the default: prices from more trusted sources count more. Step 3 – Adjustments: The raw average is then adjusted for four differences between the benchmark data and your current quote: Volume – large orders are usually cheaper per unit than small ones. Specification – a higher-spec product should cost more; lower-spec should cost less. Location – some locations cost more to deliver to than others. Service Level – a premium SLA should cost more than a standard one. Inflation/Index – historical prices are adjusted to today's market level using a price index. Step 4 – Output: The final adjusted benchmark price is compared to the supplier's quoted price to produce a variance (£ and %).
A6: THE FIVE SHEETS YOU WILL USE DAY-TO-DAY
A7: 1. Benchmark Settings – Change the benchmark method (weighted/simple/median), minimum data point threshold, and the size of each adjustment factor here. Every formula reads from this sheet. 2. Location Index Table – Add or update location cost indices here (e.g. London = 1.07 means London is 7% more expensive than the UK baseline). 3. Index Table – Stores the current market price index for each category (e.g. IT Hardware index is currently 112). Update this when you refresh the workbook. 4. Internal Benchmark Data – Paste or load your historical internal prices here. Each row is one historical data point. Do not delete the header row. 5. External DB Benchmark Extract – Paste external benchmark rows here (from a spend warehouse, market data feed, etc.). Same column structure as Internal Benchmark Data. 6. Pricing Calculation – The main working sheet. Enter deal details in the BLUE columns (A–V). All columns from W onwards calculate automatically – do not type in them.
A8: COLOUR CODING IN PRICING CALCULATION
A9: BLUE background / Blue text → INPUT. You must fill these in. They are the details of the quote you are analysing (item name, quantity, quoted price, location, etc.). AMBER background / Black text → BENCHMARK AGGREGATION. Auto-calculated formulas that count data points and calculate the raw benchmark price. GREEN background / Black text → ADJUSTMENT FACTORS. Auto-calculated multipliers that adjust the benchmark to be fair for this specific quote. PEACH/ORANGE background / Black text → OUTPUTS. The final adjusted benchmark and variance figures. GREY background → AUTO-CALCULATED. Never type over grey or amber or green or peach cells.
A10: MINIMUM DATA POINTS GATE
A11: If there are fewer than 3 comparable data points (default; change in Benchmark Settings), all benchmark and adjustment columns will show blank. This prevents the workbook from presenting an unreliable benchmark. Add more data to the Internal or External benchmark sheets to unlock the calculation.
A12: ADDING YOUR OWN DATA
... A24: Benchmark shows blank / all zeros: • Check that Total Data Points (col Y) meets the minimum in Benchmark Settings. If Y = 0, no matching rows were found. • Verify that Item Name, Unit of Measure, and Currency in Pricing Calculation exactly match what is in the benchmark data sheets. • Check that matching rows in the data sheets have Include = Yes (col S). Location adjustment looks wrong (not a number): • The location in col I of Pricing Calculation is not in the Location Index Table. Add it there or correct the spelling. Inflation adjustment looks too large or too small: • Check the Index Table current values are up to date. A large adjustment usually means the current index is much higher than the historic average in the data. Benchmark seems too high or too low vs market: • Review the data quality: are there outlier rows that should be excluded (Include=No)? • Check Source Weights — overly high weights on a few rows can skew the weighted average. • Consider switching to Median in Benchmark Settings if the data contains outliers. All formulas returning #VALUE! or #NAME?: • Do not type directly in amber, green, or peach cells. These are formula cells. • If the Formula column (B) of the Formula Map shows '=' signs as text, that is intentional and correct — those cells are descriptions, not live formulas.

Sheet Change Log
A1: Change Log – Record all material changes to this workbook here
A2: Version | B2: Date | C2: Changed By | D2: Sheet(s) Affected | E2: Nature of Change | F2: Approved By
A3: e.g. v1.0, v1.1 | B3: DD/MM/YYYY | C3: Name of person who made the change | D3: e.g. Benchmark Settings, Index Table | E3: Brief description of what changed and why | F3: Name of approver (e.g. Procurement Lead)
A4: v1.0 | B4: UPDATE REQUIRED | C4: UPDATE REQUIRED | D4: All | E4: Initial version — complete rebuild with explanations, formula map, and dashboard. | F4: UPDATE REQUIRED
A5: v1.1 | B5: UPDATE REQUIRED | C5: UPDATE REQUIRED | D5: Location Index Table, Pricing Calculation, Data Sheets | E5: Added Location Type column. Added Source Weight traceability (Weighted Price col O). Fixed VLOOKUP column reference. Fixed Include flag column reference after Weighted Price insert. Added Combined Adjustment Factor (col AY) and Benchmark Confidence (col AZ). Added data validation on Include flag and Location fields. Added Source/Basis to Index and Location tables. Corrected Adjustment Formula Guide settings row references. | F5: UPDATE REQUIRED

Sheet Benchmark Settings
A1: Benchmark Settings – Central Configuration (all formulas read from this sheet)
A2: Setting | B2: Value | C2: What this setting does
A3: CORE SETTINGS
A4: Minimum Comparable Data Points | B4: 3 | C4: The benchmark will not be shown unless the total number of matching internal + external data points is at least this number. Default = 3. Increase to require more evidence before trusting a benchmark.
A5: Benchmark Method | B5: Weighted Average | C5: How the raw benchmark price is calculated from the data points. Options: 'Weighted Average' (default – recommended), 'Simple Average', 'Median'. Change the exact text here to switch method.
A6: VOLUME ADJUSTMENT SETTINGS
A7: Volume Elasticity | B7: 0.06 | C7: Controls the strength of the volume discount/premium curve. Formula: (Target Qty / Benchmark Ref Qty) ^ (−Elasticity). 0.06 means doubling the quantity reduces unit price by ~4%. Higher = stronger volume effect.
A8: Volume Min Factor | B8: 0.85 | C8: Floor cap on the volume adjustment. The adjustment can never go below 0.85 (i.e. never grant more than 15% volume discount). Prevents extreme adjustments.
A9: Volume Max Factor | B9: 1.15 | C9: Ceiling cap on the volume adjustment. The adjustment can never exceed 1.15 (i.e. never add more than 15% low-volume premium).
A10: SPECIFICATION ADJUSTMENT SETTINGS
A11: Specification Score Factor | B11: 0.03 | C11: Each 1-point difference between the requested spec score and the benchmark average spec score changes the benchmark by this factor. E.g. 0.03 means a score 2 points above average → +6% on benchmark.
A12: Specification Min Factor | B12: 0.9 | C12: Floor cap on the specification adjustment. Max 10% reduction.
A13: Specification Max Factor | B13: 1.2 | C13: Ceiling cap on the specification adjustment. Max 20% addition.
A14: SERVICE LEVEL ADJUSTMENT SETTINGS
A15: Service Level Score Factor | B15: 0.025 | C15: Each 1-point difference between the requested SLA score and the benchmark average SLA score changes the benchmark by this factor. 0.025 means a score 2 points above average → +5% on benchmark.
A16: Service Level Min Factor | B16: 0.9 | C16: Floor cap on the service level adjustment.
A17: Service Level Max Factor | B17: 1.25 | C17: Ceiling cap on the service level adjustment.
A18: DEFAULTS
A19: Default Location Index | B19: 1 | C19: Used when a location cannot be found in the Location Index Table. 1.0 = no adjustment. Only change if your baseline location has a different cost level.
A20: Default Current Index | B20: 1 | C20: Used when an Index ID cannot be found in the Index Table. 1.0 = no inflation adjustment.

Sheet Location Index Table
A1: Location Index Table – Geographic Cost Indices for the Location Adjustment Formula
A2: Location | B2: Location Type | C2: Location Cost Index | D2: Notes / Explanation | E2: Source / Basis
A3: Name used in Location col of data sheets | B3: Country · City · Region · Delivery Mode | C3: 1.00 = baseline. Higher = more expensive | D3: Context for this entry | E3: Evidence or rationale for this cost index value
A4: UK | B4: Country | C4: 1 | D4: UK national baseline – all other indices are relative to this | E4: ONS / CIPS UK baseline – set to 1.0 by definition
A5: London | B5: City | C5: 1.07 | D5: Higher labour and property costs push prices 7% above UK baseline | E5: CBRE London office cost premium data; Knight Frank labour cost index
A6: North England | B6: Region | C6: 0.94 | D6: Lower average costs than UK baseline | E6: ONS regional cost differential (North vs UK average)
A7: EU | B7: Country / Bloc | C7: 1.03 | D7: European average – slight uplift for cross-border costs | E7: Eurostat cross-border procurement cost data; CIPS European index
A8: US | B8: Country | C8: 1.12 | D8: US delivery and support premium | E8: BLS / Gartner US IT services cost index vs UK baseline
A9: India | B9: Country | C9: 0.74 | D9: Significantly lower labour cost index | E9: NASSCOM / Everest Group offshore delivery cost benchmark
A10: Global Remote | B10: Delivery Mode | C10: 0.88 | D10: Remote-delivered service at blended rate, no physical site cost | E10: Internal blended cost model for fully remote-delivered services
A11: HOW TO ADD A NEW LOCATION: Add a row above this line. Set Location Type (Country / City / Region / Delivery Mode), Index (1.0 = UK baseline), and Source. The VLOOKUP in Pricing Calculation col AI will pick it up automatically.

Sheet Index Table
A1: Index Table – Current Price Index Values Used by the Inflation / Index Adjustment Formula
A2: Index ID | B2: Index Name | C2: Current Index Value | D2: Notes | E2: Source / Basis | F2: Last Updated
A3: ID used in all data sheets and benchmark rows | B3: Full name for reference | C3: UPDATE THIS VALUE when you refresh the workbook | D3: Source and guidance | E3: Where does this index number come from? Name the publication, dataset, or internal calculation used. | F3: Date this index value was last reviewed and updated in this workbook. Format: DD/MM/YYYY.
A4: IT-HARDWARE | B4: IT Hardware Cost Index | C4: 112 | D4: Update from industry hardware price index. Baseline = 100. | E4: CIPS / Gartner IT Pricing Index | F4: UPDATE REQUIRED
A5: SOFTWARE-SAAS | B5: Software / SaaS Index | C5: 118 | D5: Update from software licence/SaaS pricing index. | E5: Gartner SaaS Pricing Tracker | F5: UPDATE REQUIRED
A6: FACILITIES-LABOUR | B6: Facilities Labour Index | C6: 126 | D6: Update from facilities management or labour cost index. | E6: ONS Labour Cost Index | F6: UPDATE REQUIRED
A7: NETWORK-SUPPORT | B7: Network Support Services Index | C7: 120 | D7: Update from network services benchmark index. | E7: TechMarket View Managed Services Index | F7: UPDATE REQUIRED
A8: DESKTOP-MS | B8: Desktop Managed Service Index | C8: 122 | D8: Update from managed services benchmark index. | E8: TechMarket View Managed Services Index | F8: UPDATE REQUIRED
A9: HOW TO USE: The 'Current Index Value' column (C) is what you update periodically to reflect current market conditions. The benchmark data rows each store the index value at the time of the historical price. The Inflation Adjustment formula divides Current Index by Historical Index to bring old prices up (or down) to today's level. Example: Historical price recorded when index = 104. Current index = 112. Adjustment = 112/104 = 1.077. The benchmark is uplifted by 7.7% to reflect cost increases.

Sheet Internal Benchmark Data
A1: Internal Benchmark Data
A2: Benchmark Point ID | B2: Item Name | C2: Category | D2: Specification Group | E2: Specification Score | F2: Unit of Measure | G2: Currency | H2: Location | I2: Location Cost Index | J2: Service Level | K2: SLA Score | L2: Historical Quantity | M2: Raw Unit Price | N2: Source Weight | P2: Effective Date | Q2: Index ID | R2: Index Value At Price Date | S2: Include in Benchmark? | T2: Source Type | U2: Source System | V2: Source Database | W2: Source Table/View | X2: Source Record ID | Y2: Notes | Z2: Benchmark Key
A3: Unique ID for this data row. Must not be duplicated. | B3: The product or service name. Must exactly match the item name used in the Pricing Calculation sheet. | C3: Category for filtering and governance. | D3: Descriptive spec grouping (e.g. 'Standard business laptop'). | E3: Score from 1 to 10 for the specification level. Higher = premium spec. Must use the same scoring model across all rows. | F3: The unit (Each, Month, Licence, User/Month, etc.). Must match exactly what is in the Pricing Calculation sheet. | G3: ISO currency code (e.g. GBP). Prices must already be converted to a common currency before loading. | H3: Where the product/service was delivered. Must match a value in the Location Index Table. | I3: Cost index for this location. Looked up from the Location Index Table when data is loaded. | J3: SLA category label (e.g. Standard, Enhanced, Premium). | K3: Score from 1 to 10 for the service level. Must use the same scoring model as the Pricing Calculation sheet. | L3: The quantity purchased in this historical transaction. Used to calculate the benchmark reference quantity for volume adjustment. | M3: The unit price from the historical transaction. This is the core benchmark price input. Must be currency-normalised. | N3: Confidence/quality weight for this data row (0.5–1.5). Higher = more trusted. Default = 1.0. | O3: Weighted Price (Price × Weight) | P3: Date of the transaction or price observation. Used for audit and indexation. | Q3: The price index that applies to this item (e.g. IT-HARDWARE). Must match a row in the Index Table. | R3: The value of the Index ID at the Effective Date. Used by the Inflation/Index Adjustment formula. | S3: Yes or No. Only rows marked Yes are included in benchmark calculations. Use No to exclude outliers. | T3: e.g. 'Internal Historical', 'External Database', 'Market Benchmark'. | U3: The system or application the price came from (e.g. ERP, Spend Warehouse). | V3: Database or data store name for audit trail. | W3: Table or view name within the source database. | X3: The original row/record identifier from the source system. | Y3: Free-text notes about this data point. | Z3: Auto-generated key = Item Name|UOM|Currency. Used for diagnostics.
A4: INT0001 | B4: Laptop | C4: IT Hardware | D4: Standard business laptop | E4: 6 | F4: Each | G4: GBP | H4: UK | I4: 1 | J4: Standard | K4: 5 | L4: 50 | M4: 780 | N4: 0.8 | O4: =M4*N4 -> 624 | P4: 45292 | Q4: IT-HARDWARE | R4: 104 | S4: Yes | T4: Internal Historical | U4: ERP / P2P | V4: internal_procurement | W4: po_invoice_quote_history | X4: POINV-00001 | Y4: Internal comparable data point | Z4: Laptop|Each|GBP
A5: INT0002 | B5: Laptop | C5: IT Hardware | D5: Standard business laptop | E5: 6.2 | F5: Each | G5: GBP | H5: London | I5: 1.07 | J5: Standard | K5: 5 | L5: 60 | M5: 805 | N5: 0.9 | O5: =M5*N5 -> 724.5 | P5: 45689 | Q5: IT-HARDWARE | R5: 105 | S5: Yes | T5: Internal Historical | U5: ERP / P2P | V5: internal_procurement | W5: po_invoice_quote_history | X5: POINV-00002 | Y5: Internal comparable data point | Z5: Laptop|Each|GBP
A6: INT0003 | B6: Laptop | C6: IT Hardware | D6: Standard business laptop | E6: 6.4 | F6: Each | G6: GBP | H6: EU | I6: 1.03 | J6: Standard | K6: 5 | L6: 75 | M6: 820 | N6: 1 | O6: =M6*N6 -> 820 | P6: 45352 | Q6: IT-HARDWARE | R6: 105 | S6: Yes | T6: Internal Historical | U6: ERP / P2P | V6: internal_procurement | W6: po_invoice_quote_history | X6: POINV-00003 | Y6: Internal comparable data point | Z6: Laptop|Each|GBP
A7: INT0004 | B7: Laptop | C7: IT Hardware | D7: Standard business laptop | E7: 6.5 | F7: Each | G7: GBP | H7: UK | I7: 1 | J7: Standard | K7: 5 | L7: 80 | M7: 835 | N7: 1.1 | O7: =M7*N7 -> 918.5 | P7: 45748 | Q7: IT-HARDWARE | R7: 106 | S7: Yes | T7: Internal Historical | U7: ERP / P2P | V7: internal_procurement | W7: po_invoice_quote_history | X7: POINV-00004 | Y7: Internal comparable data point | Z7: Laptop|Each|GBP
A8: INT0005 | B8: Laptop | C8: IT Hardware | D8: Standard business laptop | E8: 6.7 | F8: Each | G8: GBP | H8: London | I8: 1.07 | J8: Standard | K8: 5 | L8: 90 | M8: 850 | N8: 1 | O8: =M8*N8 -> 850 | P8: 45413 | Q8: IT-HARDWARE | R8: 107 | S8: Yes | T8: Internal Historical | U8: ERP / P2P | V8: internal_procurement | W8: po_invoice_quote_history | X8: POINV-00005 | Y8: Internal comparable data point | Z8: Laptop|Each|GBP
A9: INT0006 | B9: Laptop | C9: IT Hardware | D9: Standard business laptop | E9: 6.8 | F9: Each | G9: GBP | H9: EU | I9: 1.03 | J9: Standard | K9: 5 | L9: 100 | M9: 860 | N9: 0.9 | O9: =M9*N9 -> 774 | P9: 45809 | Q9: IT-HARDWARE | R9: 107 | S9: Yes | T9: Internal Historical | U9: ERP / P2P | V9: internal_procurement | W9: po_invoice_quote_history | X9: POINV-00006 | Y9: Internal comparable data point | Z9: Laptop|Each|GBP
A10: INT0007 | B10: Laptop | C10: IT Hardware | D10: Standard business laptop | E10: 7 | F10: Each | G10: GBP | H10: UK | I10: 1 | J10: Standard | K10: 5 | L10: 110 | M10: 875 | N10: 1.2 | O10: =M10*N10 -> 1050 | P10: 45474 | Q10: IT-HARDWARE | R10: 108 | S10: Yes | T10: Internal Historical | U10: ERP / P2P | V10: internal_procurement | W10: po_invoice_quote_history | X10: POINV-00007 | Y10: Internal comparable data point | Z10: Laptop|Each|GBP
A11: INT0008 | B11: M365 Licence | C11: Software | D11: Business standard licence | E11: 5 | F11: Licence | G11: GBP | H11: UK | I11: 1 | J11: Standard | K11: 4 | L11: 100 | M11: 15.8 | N11: 0.8 | O11: =M11*N11 -> 12.64 | P11: 45292 | Q11: SOFTWARE-SAAS | R11: 107 | S11: Yes | T11: Internal Historical | U11: ERP / P2P | V11: internal_procurement | W11: po_invoice_quote_history | X11: POINV-00008 | Y11: Internal comparable data point | Z11: M365 Licence|Licence|GBP
A12: INT0009 | B12: M365 Licence | C12: Software | D12: Business standard licence | E12: 5 | F12: Licence | G12: GBP | H12: EU | I12: 1.03 | J12: Standard | K12: 4 | L12: 150 | M12: 16.1 | N12: 0.9 | O12: =M12*N12 -> 14.49 | P12: 45689 | Q12: SOFTWARE-SAAS | R12: 108 | S12: Yes | T12: Internal Historical | U12: ERP / P2P | V12: internal_procurement | W12: po_invoice_quote_history | X12: POINV-00009 | Y12: Internal comparable data point | Z12: M365 Licence|Licence|GBP
A13: INT0010 | B13: M365 Licence | C13: Software | D13: Business standard licence | E13: 5.2 | F13: Licence | G13: GBP | H13: Global Remote | I13: 0.88 | J13: Standard | K13: 5 | L13: 200 | M13: 16.4 | N13: 1 | O13: =M13*N13 -> 16.4 | P13: 45352 | Q13: SOFTWARE-SAAS | R13: 109 | S13: Yes | T13: Internal Historical | U13: ERP / P2P | V13: internal_procurement | W13: po_invoice_quote_history | X13: POINV-00010 | Y13: Internal comparable data point | Z13: M365 Licence|Licence|GBP
A14: INT0011 | B14: M365 Licence | C14: Software | D14: Business standard licence | E14: 5.4 | F14: Licence | G14: GBP | H14: UK | I14: 1 | J14: Standard | K14: 5 | L14: 250 | M14: 16.7 | N14: 1.1 | O14: =M14*N14 -> 18.37 | P14: 45748 | Q14: SOFTWARE-SAAS | R14: 110 | S14: Yes | T14: Internal Historical | U14: ERP / P2P | V14: internal_procurement | W14: po_invoice_quote_history | X14: POINV-00011 | Y14: Internal comparable data point | Z14: M365 Licence|Licence|GBP
A15: INT0012 | B15: M365 Licence | C15: Software | D15: Business standard licence | E15: 5.5 | F15: Licence | G15: GBP | H15: EU | I15: 1.03 | J15: Standard | K15: 5 | L15: 300 | M15: 17 | N15: 1 | O15: =M15*N15 -> 17 | P15: 45413 | Q15: SOFTWARE-SAAS | R15: 111 | S15: Yes | T15: Internal Historical | U15: ERP / P2P | V15: internal_procurement | W15: po_invoice_quote_history | X15: POINV-00012 | Y15: Internal comparable data point | Z15: M365 Licence|Licence|GBP
... A39: INT9991 | B39: Laptop | C39: IT Hardware | D39: Legacy laptop | E39: 3.5 | F39: Each | G39: GBP | H39: UK | I39: 1 | J39: Basic | K39: 3 | L39: 20 | M39: 410 | N39: 0.5 | O39: =M39*N39 -> 205 | P39: 45047 | Q39: IT-HARDWARE | R39: 100 | S39: No | T39: Internal Historical | U39: ERP / P2P | V39: internal_procurement | W39: po_invoice_quote_history | X39: POINV-9991 | Y39: Excluded – obsolete spec | Z39: Laptop|Each|GBP
O40: =M40*N40 -> 0
O41: =M41*N41 -> 0
O42: =M42*N42 -> 0
O43: =M43*N43 -> 0
O44: =M44*N44 -> 0
O45: =M45*N45 -> 0
O46: =M46*N46 -> 0
O47: =M47*N47 -> 0
O48: =M48*N48 -> 0
O49: =M49*N49 -> 0
O50: =M50*N50 -> 0
O51: =M51*N51 -> 0
... O509: =M509*N509 -> 0

Sheet External DB Benchmark Extract
A1: External DB Benchmark Extract
A2: Benchmark Point ID | B2: Item Name | C2: Category | D2: Specification Group | E2: Specification Score | F2: Unit of Measure | G2: Currency | H2: Location | I2: Location Cost Index | J2: Service Level | K2: SLA Score | L2: Historical Quantity | M2: Raw Unit Price | N2: Source Weight | P2: Effective Date | Q2: Index ID | R2: Index Value At Price Date | S2: Include in Benchmark? | T2: Source Type | U2: Source System | V2: Source Database | W2: Source Table/View | X2: Source Record ID | Y2: Notes | Z2: Benchmark Key
A3: Unique ID for this data row. Must not be duplicated. | B3: The product or service name. Must exactly match the item name used in the Pricing Calculation sheet. | C3: Category for filtering and governance. | D3: Descriptive spec grouping (e.g. 'Standard business laptop'). | E3: Score from 1 to 10 for the specification level. Higher = premium spec. Must use the same scoring model across all rows. | F3: The unit (Each, Month, Licence, User/Month, etc.). Must match exactly what is in the Pricing Calculation sheet. | G3: ISO currency code (e.g. GBP). Prices must already be converted to a common currency before loading. | H3: Where the product/service was delivered. Must match a value in the Location Index Table. | I3: Cost index for this location. Looked up from the Location Index Table when data is loaded. | J3: SLA category label (e.g. Standard, Enhanced, Premium). | K3: Score from 1 to 10 for the service level. Must use the same scoring model as the Pricing Calculation sheet. | L3: The quantity purchased in this historical transaction. Used to calculate the benchmark reference quantity for volume adjustment. | M3: The unit price from the historical transaction. This is the core benchmark price input. Must be currency-normalised. | N3: Confidence/quality weight for this data row (0.5–1.5). Higher = more trusted. Default = 1.0. | O3: Weighted Price (Price × Weight) | P3: Date of the transaction or price observation. Used for audit and indexation. | Q3: The price index that applies to this item (e.g. IT-HARDWARE). Must match a row in the Index Table. | R3: The value of the Index ID at the Effective Date. Used by the Inflation/Index Adjustment formula. | S3: Yes or No. Only rows marked Yes are included in benchmark calculations. Use No to exclude outliers. | T3: e.g. 'Internal Historical', 'External Database', 'Market Benchmark'. | U3: The system or application the price came from (e.g. ERP, Spend Warehouse). | V3: Database or data store name for audit trail. | W3: Table or view name within the source database. | X3: The original row/record identifier from the source system. | Y3: Free-text notes about this data point. | Z3: Auto-generated key = Item Name|UOM|Currency. Used for diagnostics.
A4: EXT0001 | B4: Laptop | C4: IT Hardware | D4: Standard business laptop | E4: 6.9 | F4: Each | G4: GBP | H4: London | I4: 1.07 | J4: Standard | K4: 6 | L4: 125 | M4: 890 | N4: 1 | O4: =M4*N4 -> 890 | P4: 45658 | Q4: IT-HARDWARE | R4: 108 | S4: Yes | T4: External Database | U4: SpendWarehouse / MarketData | V4: market_and_spend_dw | W4: vw_external_benchmark_prices | X4: EXTSRC-00001 | Y4: Loaded from external DB extract | Z4: Laptop|Each|GBP
A5: EXT0002 | B5: Laptop | C5: IT Hardware | D5: Standard business laptop | E5: 7.1 | F5: Each | G5: GBP | H5: EU | I5: 1.03 | J5: Standard | K5: 5 | L5: 140 | M5: 910 | N5: 1.2 | O5: =M5*N5 -> 1092 | P5: 45689 | Q5: IT-HARDWARE | R5: 109 | S5: Yes | T5: External Database | U5: SpendWarehouse / MarketData | V5: market_and_spend_dw | W5: vw_external_benchmark_prices | X5: EXTSRC-00002 | Y5: Loaded from external DB extract | Z5: Laptop|Each|GBP
A6: EXT0003 | B6: Laptop | C6: IT Hardware | D6: Standard business laptop | E6: 7 | F6: Each | G6: GBP | H6: UK | I6: 1 | J6: Standard | K6: 6 | L6: 150 | M6: 925 | N6: 1.1 | O6: =M6*N6 -> 1017.5 | P6: 45717 | Q6: IT-HARDWARE | R6: 110 | S6: Yes | T6: External Database | U6: SpendWarehouse / MarketData | V6: market_and_spend_dw | W6: vw_external_benchmark_prices | X6: EXTSRC-00003 | Y6: Loaded from external DB extract | Z6: Laptop|Each|GBP
A7: EXT0004 | B7: Laptop | C7: IT Hardware | D7: Standard business laptop | E7: 7.2 | F7: Each | G7: GBP | H7: London | I7: 1.07 | J7: Standard | K7: 5 | L7: 175 | M7: 940 | N7: 0.95 | O7: =M7*N7 -> 893 | P7: 45748 | Q7: IT-HARDWARE | R7: 110 | S7: Yes | T7: External Database | U7: SpendWarehouse / MarketData | V7: market_and_spend_dw | W7: vw_external_benchmark_prices | X7: EXTSRC-00004 | Y7: Loaded from external DB extract | Z7: Laptop|Each|GBP
A8: EXT0005 | B8: Laptop | C8: IT Hardware | D8: Standard business laptop | E8: 7.4 | F8: Each | G8: GBP | H8: EU | I8: 1.03 | J8: Standard | K8: 6 | L8: 200 | M8: 955 | N8: 1.3 | O8: =M8*N8 -> 1241.5 | P8: 45778 | Q8: IT-HARDWARE | R8: 111 | S8: Yes | T8: External Database | U8: SpendWarehouse / MarketData | V8: market_and_spend_dw | W8: vw_external_benchmark_prices | X8: EXTSRC-00005 | Y8: Loaded from external DB extract | Z8: Laptop|Each|GBP
A9: EXT0006 | B9: M365 Licence | C9: Software | D9: Business standard licence | E9: 6 | F9: Licence | G9: GBP | H9: EU | I9: 1.03 | J9: Standard | K9: 5 | L9: 500 | M9: 17.6 | N9: 1 | O9: =M9*N9 -> 17.6 | P9: 45658 | Q9: SOFTWARE-SAAS | R9: 114 | S9: Yes | T9: External Database | U9: SpendWarehouse / MarketData | V9: market_and_spend_dw | W9: vw_external_benchmark_prices | X9: EXTSRC-00006 | Y9: Loaded from external DB extract | Z9: M365 Licence|Licence|GBP
A10: EXT0007 | B10: M365 Licence | C10: Software | D10: Business standard licence | E10: 6.1 | F10: Licence | G10: GBP | H10: Global Remote | I10: 0.88 | J10: Standard | K10: 6 | L10: 600 | M10: 17.9 | N10: 1.2 | O10: =M10*N10 -> 21.48 | P10: 45689 | Q10: SOFTWARE-SAAS | R10: 115 | S10: Yes | T10: External Database | U10: SpendWarehouse / MarketData | V10: market_and_spend_dw | W10: vw_external_benchmark_prices | X10: EXTSRC-00007 | Y10: Loaded from external DB extract | Z10: M365 Licence|Licence|GBP
A11: EXT0008 | B11: M365 Licence | C11: Software | D11: Business standard licence | E11: 6.2 | F11: Licence | G11: GBP | H11: UK | I11: 1 | J11: Standard | K11: 6 | L11: 700 | M11: 18.2 | N11: 1.1 | O11: =M11*N11 -> 20.02 | P11: 45717 | Q11: SOFTWARE-SAAS | R11: 116 | S11: Yes | T11: External Database | U11: SpendWarehouse / MarketData | V11: market_and_spend_dw | W11: vw_external_benchmark_prices | X11: EXTSRC-00008 | Y11: Loaded from external DB extract | Z11: M365 Licence|Licence|GBP
A12: EXT0009 | B12: Facilities Cleaning | C12: Facilities | D12: Office cleaning monthly service | E12: 6.3 | F12: Month | G12: GBP | H12: London | I12: 1.07 | J12: Standard | K12: 6 | L12: 24 | M12: 4050 | N12: 1 | O12: =M12*N12 -> 4050 | P12: 45658 | Q12: FACILITIES-LABOUR | R12: 120 | S12: Yes | T12: External Database | U12: SpendWarehouse / MarketData | V12: market_and_spend_dw | W12: vw_external_benchmark_prices | X12: EXTSRC-00009 | Y12: Loaded from external DB extract | Z12: Facilities Cleaning|Month|GBP
A13: EXT0010 | B13: Facilities Cleaning | C13: Facilities | D13: Office cleaning monthly service | E13: 6.5 | F13: Month | G13: GBP | H13: North England | I13: 0.94 | J13: Standard | K13: 7 | L13: 24 | M13: 4100 | N13: 1.2 | O13: =M13*N13 -> 4920 | P13: 45689 | Q13: FACILITIES-LABOUR | R13: 121 | S13: Yes | T13: External Database | U13: SpendWarehouse / MarketData | V13: market_and_spend_dw | W13: vw_external_benchmark_prices | X13: EXTSRC-00010 | Y13: Loaded from external DB extract | Z13: Facilities Cleaning|Month|GBP
A14: EXT0011 | B14: Facilities Cleaning | C14: Facilities | D14: Office cleaning monthly service | E14: 6.6 | F14: Month | G14: GBP | H14: UK | I14: 1 | J14: Standard | K14: 7 | L14: 36 | M14: 4180 | N14: 1.1 | O14: =M14*N14 -> 4598 | P14: 45717 | Q14: FACILITIES-LABOUR | R14: 122 | S14: Yes | T14: External Database | U14: SpendWarehouse / MarketData | V14: market_and_spend_dw | W14: vw_external_benchmark_prices | X14: EXTSRC-00011 | Y14: Loaded from external DB extract | Z14: Facilities Cleaning|Month|GBP
A15: EXT0012 | B15: Network Support | C15: IT Services | D15: Network support monthly service | E15: 7 | F15: Month | G15: GBP | H15: Global Remote | I15: 0.88 | J15: Enhanced | K15: 8 | L15: 48 | M15: 1300 | N15: 1 | O15: =M15*N15 -> 1300 | P15: 45658 | Q15: NETWORK-SUPPORT | R15: 115 | S15: Yes | T15: External Database | U15: SpendWarehouse / MarketData | V15: market_and_spend_dw | W15: vw_external_benchmark_prices | X15: EXTSRC-00012 | Y15: Loaded from external DB extract | Z15: Network Support|Month|GBP
... A21: EXT9991 | B21: Laptop | C21: IT Hardware | D21: High-end workstation | E21: 9.5 | F21: Each | G21: GBP | H21: US | I21: 1.12 | J21: Premium | K21: 9 | L21: 25 | M21: 1600 | N21: 0.7 | O21: =M21*N21 -> 1120 | P21: 45809 | Q21: IT-HARDWARE | R21: 111 | S21: No | T21: External Database | U21: MarketData | V21: market_and_spend_dw | W21: vw_external_benchmark_prices | X21: EXTSRC-9991 | Y21: Excluded – non-comparable high-spec outlier | Z21: Laptop|Each|GBP
O22: =M22*N22 -> 0
O23: =M23*N23 -> 0
O24: =M24*N24 -> 0
O25: =M25*N25 -> 0
O26: =M26*N26 -> 0
O27: =M27*N27 -> 0
O28: =M28*N28 -> 0
O29: =M29*N29 -> 0
O30: =M30*N30 -> 0
O31: =M31*N31 -> 0
O32: =M32*N32 -> 0
O33: =M33*N33 -> 0
... O509: =M509*N509 -> 0

Sheet Pricing Calculation
A1: Pricing Calculation — BLUE columns: fill in manually | All other columns: auto-calculated — do not edit
A2: INPUT FIELDS (columns A–V) — fill these in with your quote details | W2: BENCHMARK AGGREGATION (columns W–AM) — auto-calculated from benchmark data sheets | AN2: ADJUSTMENT FACTORS (columns AN–AR) — auto-calculated multipliers | AS2: OUTPUTS (columns AS–AX) — final benchmark, totals, and variance
A3: Deal ID | B3: Item Name | C3: Supplier Name | D3: Supplier Quote Ref | E3: Category | F3: Quantity | G3: Unit of Measure | H3: Currency | I3: Location | J3: Requested Spec Score | K3: Service Level | L3: Requested SLA Score | M3: Index ID | N3: Quoted Unit Price (£) | O3: Delivery Cost (£) | P3: Implementation Cost (£) | Q3: Support Cost (£) | R3: Risk Premium (£) | S3: Discount / Rebate (£) | T3: Supplier Risk Penalty [INFO ONLY] | U3: Contract Risk Penalty [INFO ONLY] | V3: Strategic Supplier Bonus [INFO ONLY] | W3: Internal Data Points | X3: External Data Points | Y3: Total Data Points | Z3: Int. Wtd Price Sum | AA3: Ext. Wtd Price Sum | AB3: Total Source Weight | AC3: Simple Average Benchmark | AD3: Weighted Avg Benchmark | AE3: Median Benchmark | AF3: Selected Benchmark Price | AG3: Benchmark Ref Quantity | AH3: Benchmark Avg Spec Score | AI3: Target Location Index | AJ3: Benchmark Avg Loc. Index | AK3: Benchmark Avg SLA Score | AL3: Current Index Value | AM3: Benchmark Avg Historic Index | AN3: Volume Adjustment | AO3: Spec Adjustment | AP3: Location Adjustment | AQ3: SLA Adjustment | AR3: Inflation/Index Adj. | AS3: Final Adj. Benchmark (£) | AT3: Quoted Total Cost (£) | AU3: Benchmark Total Cost (£) | AV3: Unit Price Variance (£) | AW3: Unit Price Variance (%) | AX3: Total Cost Gap (£) | AY3: Combined Adj. Factor | AZ3: Benchmark Confidence
A4: Unique identifier for the deal or RFQ line (e.g. D001). Used to group rows. | B4: The product or service being quoted. Must match exactly what is in the benchmark data sheets. | C4: Name of the supplier submitting the quote. | D4: Supplier's own quote reference number for audit trail. | E4: Category of the item (e.g. IT Hardware, Facilities). For reference and filtering. | F4: The quantity being quoted. Used in the volume adjustment and total cost calculation. | G4: Unit of the item (e.g. Each, Month, Licence). Must match the benchmark data exactly. | H4: ISO currency code (e.g. GBP). Must match the benchmark data. | I4: Where this will be delivered or used. Looked up in the Location Index Table for adjustment. | J4: Score from 1-10 for the specification you are buying. 10 = highest spec. Compare to benchmark avg spec score (col AH). | K4: The SLA/service level required (e.g. Standard, Enhanced, Premium). | L4: Score from 1-10 for the service level you need. Compare to benchmark avg SLA score (col AK). | M4: The price index that applies to this item. Must match a row in the Index Table sheet. | N4: The supplier's unit price from their quote. | O4: Delivery/logistics cost from the quote. Enter 0 if included in unit price. | P4: One-off implementation or setup cost. Enter 0 if not applicable. | Q4: Annual or contract support fees. Enter 0 if included in unit price. | R4: Any additional risk-based cost applied. Enter 0 if not used. | S4: Any discount or rebate applied (as a positive number – it reduces cost). | T4: Supplier Risk Penalty (INFORMATIONAL ONLY – not used in any formula) Risk score for supplier reliability (0–100). Captured for governance and due diligence purposes. To incorporate into pricing, wire into col N (Quoted Unit Price) manually or build a separate risk-adjusted price column. | U4: Contract Risk Penalty (INFORMATIONAL ONLY – not used in any formula) Risk score for contractual exposure (0–100). Recorded for governance. See note for col T above regarding how to incorporate if needed. | V4: Strategic Supplier Bonus (INFORMATIONAL ONLY – not used in any formula) Bonus score for strategic/preferred supplier status (0–100). Recorded for governance. Not factored into the benchmark comparison. Useful for qualitative scoring alongside the price analysis. | W4: COUNT of internal benchmark rows matching this item/UOM/currency that are marked Include=Yes. | X4: COUNT of external DB benchmark rows matching this item/UOM/currency that are marked Include=Yes. | Y4: Internal + External data point count. Must be ≥ the Minimum in Benchmark Settings or all benchmark columns stay blank. | Z4: Sum of (Raw Unit Price × Source Weight) for all matching internal rows. Used for weighted average. | AA4: Sum of (Raw Unit Price × Source Weight) for all matching external rows. Used for weighted average. | AB4: Sum of Source Weight (col N) for all matching rows across both data sheets — this is the denominator for the weighted average. To verify: in each data sheet, filter to this item/UOM/currency + Include=Yes, and sum col N (Weight). Col O (Weighted Price = Price × Weight) shows each row's contribution to the numerators in cols Z and AA. | AC4: All matching prices added up and divided equally by the total count. Every data point counts the same. | AD4: Sum of (price × weight) divided by total weight. Higher-weight sources have more influence. Default method. | AE4: The middle price when all matching prices are sorted. Reduces the effect of high or low outliers. Requires Excel 365. | AF4: The raw benchmark price selected based on the Benchmark Method in Benchmark Settings (Weighted Avg by default). | AG4: Weighted average of historical quantities from all matching data points. Used as the 'normal' quantity for volume adjustment. | AH4: Weighted average spec score across all matching benchmark rows. Compared to your Requested Spec Score. | AI4: The cost index for the location in column I, looked up from the Location Index Table. | AJ4: Weighted average location cost index across all matching benchmark rows. | AK4: Weighted average SLA score across all matching benchmark rows. | AL4: The current value of the price index for this item's category, looked up from the Index Table. | AM4: Weighted average of the index value at the time each benchmark price was recorded. | AN4: Factor for quantity scale. > 1.0 = buying less than benchmark avg (premium). < 1.0 = buying more (discount). Formula: (Qty / Ref Qty)^(−Elasticity), capped by settings. | AO4: Factor for specification difference. > 1.0 = requested spec is higher than benchmark avg. < 1.0 = lower. Formula: 1 + ((Req Spec − Avg Spec) × Spec Factor), capped. | AP4: Factor for geographic cost difference. = Target Location Index ÷ Benchmark Average Location Index. > 1.0 = target is more expensive than benchmark locations. | AQ4: Factor for service level difference. > 1.0 = requesting higher SLA than benchmark avg. < 1.0 = lower SLA. Formula: 1 + ((Req SLA − Avg SLA) × SLA Factor), capped. | AR4: Factor to update historic benchmark prices to today's level. = Current Index ÷ Avg Historic Index. > 1.0 = costs have risen; benchmark is uplifted. | AS4: The benchmark after all five adjustments. This is the fair comparison price for this quote: Selected Benchmark × Volume × Spec × Location × SLA × Index. | AT4: Total cost of the quote: (Unit Price + Delivery + Implementation + Support + Risk − Discount) × Quantity. | AU4: Total cost using the adjusted benchmark price in place of the quoted unit price. | AV4: Quoted Unit Price minus Final Adjusted Benchmark. Positive = supplier is more expensive than benchmark. Negative = cheaper. | AW4: Unit price variance as a percentage of the adjusted benchmark price. | AX4: Quoted Total Cost minus Benchmark Total Cost over the full quantity. Positive = savings opportunity. Negative = quote beats benchmark. | AY4: Product of all five adjustment factors (AN × AO × AP × AQ × AR). Shows the total multiplier applied to the raw benchmark to reach the final adjusted benchmark. E.g. 0.94 means the combined adjustments reduced the benchmark by 6%. | AZ4: Categorical confidence in the benchmark based on Total Data Points (col Y). HIGH = 10+ data points. MEDIUM = 6–9. LOW = 3–5. INSUFFICIENT = below minimum. Lower confidence = treat the benchmark as indicative, not definitive.
A5: D001 | B5: Laptop | C5: Supplier A | D5: Q-1001 | E5: IT Hardware | F5: 100 | G5: Each | H5: GBP | I5: UK | J5: 7 | K5: Standard | L5: 5 | M5: IT-HARDWARE | N5: 950 | O5: 2000 | P5: 1500 | Q5: 3000 | R5: 1000 | S5: 2500 | T5: 5 | U5: 3 | V5: 2 | W5: =COUNTIFS('Internal Benchmark Data'!$B$4:$B$500,$B5,'Internal Benchmark Data'!$F$4:$F$500,$G5,'Internal Benchmark Data'!$G$4:$G$500,$H5,'Internal Benchmark Data'!$S$4:$S$500,"Yes") -> 7 | X5: =COUNTIFS('External DB Benchmark Extract'!$B$4:$B$500,$B5,'External DB Benchmark Extract'!$F$4:$F$500,$G5,'External DB Benchmark Extract'!$G$4:$G$500,$H5,'External DB Benchmark Extract'!$S$4:$S$500,"Yes") -> 5 | Y5: =$W5+$X5 -> 12 | Z5: =SUMPRODUCT(('Internal Benchmark Data'!$B$4:$B$500=$B5)*('Internal Benchmark Data'!$F$4:$F$500=$G5)*('Internal Benchmark Data'!$G$4:$G$500=$H5)*('Internal Benchmark Data'!$S$4:$S$500="Yes")*'Internal Benchmark Data'!$M$4:$M$500*'Internal Benchmark Data'!$N$4:$N$500) -> 5761 | AA5: =SUMPRODUCT(('External DB Benchmark Extract'!$B$4:$B$500=$B5)*('External DB Benchmark Extract'!$F$4:$F$500=$G5)*('External DB Benchmark Extract'!$G$4:$G$500=$H5)*('External DB Benchmark Extract'!$S$4:$S$500="Yes")*'External DB Benchmark Extract'!$M$4:$M$500*'External DB Benchmark Extract'!$N$4:$N$500) -> 5134 | AB5: =SUMPRODUCT(('Internal Benchmark Data'!$B$4:$B$500=$B5)*('Internal Benchmark Data'!$F$4:$F$500=$G5)*('Internal Benchmark Data'!$G$4:$G$500=$H5)*('Internal Benchmark Data'!$S$4:$S$500="Yes")*'Internal Benchmark Data'!$N$4:$N$500)+SUMPRODUCT(('External DB Benchmark Extract'!$B$4:$B$500=$B5)*('External DB Benchmark Extract'!$F$4:$F$500=$G5)*('External DB Benchmark Extract'!$G$4:$G$500=$H5)*('External DB Benchmark Extract'!$S$4:$S$500="Yes")*'External DB Benchmark Extract'!$N$4:$N$500) -> 12.45 | AC5: =IF($Y5<'Benchmark Settings'!$B$4,"",IFERROR(ROUND((SUMIFS('Internal Benchmark Data'!$M$4:$M$500,'Internal Benchmark Data'!$B$4:$B$500,$B5,'Internal Benchmark Data'!$F$4:$F$500,$G5,'Internal Benchmark Data'!$G$4:$G$500,$H5,'Internal Benchmark Data'!$S$4:$S$500,"Yes")+SUMIFS('External DB Benchmark Extract'!$M$4:$M$500,'External DB Benchmark Extract'!$B$4:$B$500,$B5,'External DB Benchmark Extract'!$F$4:$F$500,$G5,'External DB Benchmark Extract'!$G$4:$G$500,$H5,'External DB Benchmark Extract'!$S$4:$S$500,"Yes"))/$Y5,2),"")) -> 870.42 | AD5: =IF($Y5<'Benchmark Settings'!$B$4,"",IFERROR(ROUND(($Z5+$AA5)/$AB5,2),"")) -> 875.1 | AE5: =IF($Y5<'Benchmark Settings'!$B$4,"",IFERROR(ROUND(MEDIAN(IF(('Internal Benchmark Data'!$B$4:$B$500=$B5)*('Internal Benchmark Data'!$F$4:$F$500=$G5)*('Internal Benchmark Data'!$G$4:$G$500=$H5)*('Internal Benchmark Data'!$S$4:$S$500="Yes"),'Internal Benchmark Data'!$M$4:$M$500)),2),"")) -> 827.5 | AF5: =IF($Y5<'Benchmark Settings'!$B$4,"",IF('Benchmark Settings'!$B$5="Simple Average",$AC5,IF('Benchmark Settings'!$B$5="Median",$AE5,$AD5))) -> 875.1 | AG5: =IF($Y5<'Benchmark Settings'!$B$4,"",IFERROR(ROUND((SUMPRODUCT(('Internal Benchmark Data'!$B$4:$B$500=$B5)*('Internal Benchmark Data'!$F$4:$F$500=$G5)*('Internal Benchmark Data'!$G$4:$G$500=$H5)*('Internal Benchmark Data'!$S$4:$S$500="Yes")*'Internal Benchmark Data'!$L$4:$L$500*'Internal Benchmark Data'!$N$4:$N$500)+SUMPRODUCT(('External DB Benchmark Extract'!$B$4:$B$500=$B5)*('External DB Benchmark Extract'!$F$4:$F$500=$G5)*('External DB Benchmark Extract'!$G$4:$G$500=$H5)*('External DB Benchmark Extract'!$S$4:$S$500="Yes")*'External DB Benchmark Extract'!$L$4:$L$500*'External DB Benchmark Extract'!$N$4:$N$500))/$AB5,2),"")) -> 116.73 | AH5: =IF($Y5<'Benchmark Settings'!$B$4,"",IFERROR(ROUND((SUMPRODUCT(('Internal Benchmark Data'!$B$4:$B$500=$B5)*('Internal Benchmark Data'!$F$4:$F$500=$G5)*('Internal Benchmark Data'!$G$4:$G$500=$H5)*('Internal Benchmark Data'!$S$4:$S$500="Yes")*'Internal Benchmark Data'!$E$4:$E$500*'Internal Benchmark Data'!$N$4:$N$500)+SUMPRODUCT(('External DB Benchmark Extract'!$B$4:$B$500=$B5)*('External DB Benchmark Extract'!$F$4:$F$500=$G5)*('External DB Benchmark Extract'!$G$4:$G$500=$H5)*('External DB Benchmark Extract'!$S$4:$S$500="Yes")*'External DB Benchmark Extract'!$E$4:$E$500*'External DB Benchmark Extract'!$N$4:$N$500))/$AB5,2),"")) -> 6.81 | AI5: =IFERROR(VLOOKUP($I5,'Location Index Table'!$A:$C,3,FALSE()),'Benchmark Settings'!$B$19) -> 1 | AJ5: =IF($Y5<'Benchmark Settings'!$B$4,"",IFERROR(ROUND((SUMPRODUCT(('Internal Benchmark Data'!$B$4:$B$500=$B5)*('Internal Benchmark Data'!$F$4:$F$500=$G5)*('Internal Benchmark Data'!$G$4:$G$500=$H5)*('Internal Benchmark Data'!$S$4:$S$500="Yes")*'Internal Benchmark Data'!$I$4:$I$500*'Internal Benchmark Data'!$N$4:$N$500)+SUMPRODUCT(('External DB Benchmark Extract'!$B$4:$B$500=$B5)*('External DB Benchmark Extract'!$F$4:$F$500=$G5)*('External DB Benchmark Extract'!$G$4:$G$500=$H5)*('External DB Benchmark Extract'!$S$4:$S$500="Yes")*'External DB Benchmark Extract'!$I$4:$I$500*'External DB Benchmark Extract'!$N$4:$N$500))/$AB5,4),"")) -> 1.0322 | AK5: =IF($Y5<'Benchmark Settings'!$B$4,"",IFERROR(ROUND((SUMPRODUCT(('Internal Benchmark Data'!$B$4:$B$500=$B5)*('Internal Benchmark Data'!$F$4:$F$500=$G5)*('Internal Benchmark Data'!$G$4:$G$500=$H5)*('Internal Benchmark Data'!$S$4:$S$500="Yes")*'Internal Benchmark Data'!$K$4:$K$500*'Internal Benchmark Data'!$N$4:$N$500)+SUMPRODUCT(('External DB Benchmark Extract'!$B$4:$B$500=$B5)*('External DB Benchmark Extract'!$F$4:$F$500=$G5)*('External DB Benchmark Extract'!$G$4:$G$500=$H5)*('External DB Benchmark Extract'!$S$4:$S$500="Yes")*'External DB Benchmark Extract'!$K$4:$K$500*'External DB Benchmark Extract'!$N$4:$N$500))/$AB5,2),"")) -> 5.27 | AL5: =IFERROR(VLOOKUP($M5,'Index Table'!$A:$C,3,FALSE()),'Benchmark Settings'!$B$20) -> 112 | AM5: =IF($Y5<'Benchmark Settings'!$B$4,"",IFERROR(ROUND((SUMPRODUCT(('Internal Benchmark Data'!$B$4:$B$500=$B5)*('Internal Benchmark Data'!$F$4:$F$500=$G5)*('Internal Benchmark Data'!$G$4:$G$500=$H5)*('Internal Benchmark Data'!$S$4:$S$500="Yes")*'Internal Benchmark Data'!$R$4:$R$500*'Internal Benchmark Data'!$N$4:$N$500)+SUMPRODUCT(('External DB Benchmark Extract'!$B$4:$B$500=$B5)*('External DB Benchmark Extract'!$F$4:$F$500=$G5)*('External DB Benchmark Extract'!$G$4:$G$500=$H5)*('External DB Benchmark Extract'!$S$4:$S$500="Yes")*'External DB Benchmark Extract'!$R$4:$R$500*'External DB Benchmark Extract'!$N$4:$N$500))/$AB5,2),"")) -> 107.69 | AN5: =IF($Y5<'Benchmark Settings'!$B$4,"",IF($AF5="","",IFERROR(ROUND(MAX('Benchmark Settings'!$B$8,MIN('Benchmark Settings'!$B$9,POWER($F5/$AG5,-'Benchmark Settings'!$B$7))),4),1))) -> 1.0093 | AO5: =IF($Y5<'Benchmark Settings'!$B$4,"",IF($AF5="","",IFERROR(ROUND(MAX('Benchmark Settings'!$B$12,MIN('Benchmark Settings'!$B$13,1+(($J5-$AH5)*'Benchmark Settings'!$B$11))),4),1))) -> 1.0057 | AP5: =IF($Y5<'Benchmark Settings'!$B$4,"",IF($AF5="","",IFERROR(ROUND($AI5/$AJ5,4),1))) -> 0.9688 | AQ5: =IF($Y5<'Benchmark Settings'!$B$4,"",IF($AF5="","",IFERROR(ROUND(MAX('Benchmark Settings'!$B$16,MIN('Benchmark Settings'!$B$17,1+(($L5-$AK5)*'Benchmark Settings'!$B$15))),4),1))) -> 0.9933 | AR5: =IF($Y5<'Benchmark Settings'!$B$4,"",IF($AF5="","",IFERROR(ROUND($AL5/$AM5,4),1))) -> 1.04 | AS5: =IF($Y5<'Benchmark Settings'!$B$4,"",IF($AF5="","",IFERROR(ROUND($AF5*$AN5*$AO5*$AP5*$AQ5*$AR5,2),""))) -> 888.98 | AT5: =($N5*$F5)+$O5+$P5+$Q5+$R5-$S5 -> 100000 | AU5: =IF($AS5="","",$AS5*$F5+$O5+$P5+$Q5+$R5-$S5) -> 93898 | AV5: =IF($AS5="","",ROUND($N5-$AS5,2)) -> 61.02 | AW5: =IF($AS5="","",IFERROR(ROUND($AV5/$AS5,4),"")) -> 0.0686 | AX5: =IF($AU5="","",ROUND($AT5-$AU5,0)) -> 6102 | AY5: =IF($Y5<'Benchmark Settings'!$B$4,"",ROUND($AN5*$AO5*$AP5*$AQ5*$AR5,4)) -> 1.0159 | AZ5: =IF($Y5=0,"No Data",IF($Y5<'Benchmark Settings'!$B$4,"Insufficient",IF($Y5>=10,"HIGH",IF($Y5>=6,"MEDIUM","LOW")))) -> HIGH
A6: D002 | B6: M365 Licence | C6: Supplier C | D6: Q-2055 | E6: Software | F6: 250 | G6: Licence | H6: GBP | I6: UK | J6: 6 | K6: Standard | L6: 5 | M6: SOFTWARE-SAAS | N6: 18.5 | O6: 0 | P6: 500 | Q6: 1200 | R6: 300 | S6: 900 | T6: 3 | U6: 2 | V6: 4 | W6: =COUNTIFS('Internal Benchmark Data'!$B$4:$B$500,$B6,'Internal Benchmark Data'!$F$4:$F$500,$G6,'Internal Benchmark Data'!$G$4:$G$500,$H6,'Internal Benchmark Data'!$S$4:$S$500,"Yes") -> 7 | X6: =COUNTIFS('External DB Benchmark Extract'!$B$4:$B$500,$B6,'External DB Benchmark Extract'!$F$4:$F$500,$G6,'External DB Benchmark Extract'!$G$4:$G$500,$H6,'External DB Benchmark Extract'!$S$4:$S$500,"Yes") -> 3 | Y6: =$W6+$X6 -> 10 | Z6: =SUMPRODUCT(('Internal Benchmark Data'!$B$4:$B$500=$B6)*('Internal Benchmark Data'!$F$4:$F$500=$G6)*('Internal Benchmark Data'!$G$4:$G$500=$H6)*('Internal Benchmark Data'!$S$4:$S$500="Yes")*'Internal Benchmark Data'!$M$4:$M$500*'Internal Benchmark Data'!$N$4:$N$500) -> 115.26 | AA6: =SUMPRODUCT(('External DB Benchmark Extract'!$B$4:$B$500=$B6)*('External DB Benchmark Extract'!$F$4:$F$500=$G6)*('External DB Benchmark Extract'!$G$4:$G$500=$H6)*('External DB Benchmark Extract'!$S$4:$S$500="Yes")*'External DB Benchmark Extract'!$M$4:$M$500*'External DB Benchmark Extract'!$N$4:$N$500) -> 59.1 | AB6: =SUMPRODUCT(('Internal Benchmark Data'!$B$4:$B$500=$B6)*('Internal Benchmark Data'!$F$4:$F$500=$G6)*('Internal Benchmark Data'!$G$4:$G$500=$H6)*('Internal Benchmark Data'!$S$4:$S$500="Yes")*'Internal Benchmark Data'!$N$4:$N$500)+SUMPRODUCT(('External DB Benchmark Extract'!$B$4:$B$500=$B6)*('External DB Benchmark Extract'!$F$4:$F$500=$G6)*('External DB Benchmark Extract'!$G$4:$G$500=$H6)*('External DB Benchmark Extract'!$S$4:$S$500="Yes")*'External DB Benchmark Extract'!$N$4:$N$500) -> 10.2 | AC6: =IF($Y6<'Benchmark Settings'!$B$4,"",IFERROR(ROUND((SUMIFS('Internal Benchmark Data'!$M$4:$M$500,'Internal Benchmark Data'!$B$4:$B$500,$B6,'Internal Benchmark Data'!$F$4:$F$500,$G6,'Internal Benchmark Data'!$G$4:$G$500,$H6,'Internal Benchmark Data'!$S$4:$S$500,"Yes")+SUMIFS('External DB Benchmark Extract'!$M$4:$M$500,'External DB Benchmark Extract'!$B$4:$B$500,$B6,'External DB Benchmark Extract'!$F$4:$F$500,$G6,'External DB Benchmark Extract'!$G$4:$G$500,$H6,'External DB Benchmark Extract'!$S$4:$S$500,"Yes"))/$Y6,2),"")) -> 17.03 | AD6: =IF($Y6<'Benchmark Settings'!$B$4,"",IFERROR(ROUND(($Z6+$AA6)/$AB6,2),"")) -> 17.09 | AE6: =IF($Y6<'Benchmark Settings'!$B$4,"",IFERROR(ROUND(MEDIAN(IF(('Internal Benchmark Data'!$B$4:$B$500=$B6)*('Internal Benchmark Data'!$F$4:$F$500=$G6)*('Internal Benchmark Data'!$G$4:$G$500=$H6)*('Internal Benchmark Data'!$S$4:$S$500="Yes"),'Internal Benchmark Data'!$M$4:$M$500)),2),"")) -> 0 | AF6: =IF($Y6<'Benchmark Settings'!$B$4,"",IF('Benchmark Settings'!$B$5="Simple Average",$AC6,IF('Benchmark Settings'!$B$5="Median",$AE6,$AD6))) -> 17.09 | AG6: =IF($Y6<'Benchmark Settings'!$B$4,"",IFERROR(ROUND((SUMPRODUCT(('Internal Benchmark Data'!$B$4:$B$500=$B6)*('Internal Benchmark Data'!$F$4:$F$500=$G6)*('Internal Benchmark Data'!$G$4:$G$500=$H6)*('Internal Benchmark Data'!$S$4:$S$500="Yes")*'Internal Benchmark Data'!$L$4:$L$500*'Internal Benchmark Data'!$N$4:$N$500)+SUMPRODUCT(('External DB Benchmark Extract'!$B$4:$B$500=$B6)*('External DB Benchmark Extract'!$F$4:$F$500=$G6)*('External DB Benchmark Extract'!$G$4:$G$500=$H6)*('External DB Benchmark Extract'!$S$4:$S$500="Yes")*'External DB Benchmark Extract'!$L$4:$L$500*'External DB Benchmark Extract'!$N$4:$N$500))/$AB6,2),"")) -> 370.1 | AH6: =IF($Y6<'Benchmark Settings'!$B$4,"",IFERROR(ROUND((SUMPRODUCT(('Internal Benchmark Data'!$B$4:$B$500=$B6)*('Internal Benchmark Data'!$F$4:$F$500=$G6)*('Internal Benchmark Data'!$G$4:$G$500=$H6)*('Internal Benchmark Data'!$S$4:$S$500="Yes")*'Internal Benchmark Data'!$E$4:$E$500*'Internal Benchmark Data'!$N$4:$N$500)+SUMPRODUCT(('External DB Benchmark Extract'!$B$4:$B$500=$B6)*('External DB Benchmark Extract'!$F$4:$F$500=$G6)*('External DB Benchmark Extract'!$G$4:$G$500=$H6)*('External DB Benchmark Extract'!$S$4:$S$500="Yes")*'External DB Benchmark Extract'!$E$4:$E$500*'External DB Benchmark Extract'!$N$4:$N$500))/$AB6,2),"")) -> 5.62 | AI6: =IFERROR(VLOOKUP($I6,'Location Index Table'!$A:$C,3,FALSE()),'Benchmark Settings'!$B$19) -> 1 | AJ6: =IF($Y6<'Benchmark Settings'!$B$4,"",IFERROR(ROUND((SUMPRODUCT(('Internal Benchmark Data'!$B$4:$B$500=$B6)*('Internal Benchmark Data'!$F$4:$F$500=$G6)*('Internal Benchmark Data'!$G$4:$G$500=$H6)*('Internal Benchmark Data'!$S$4:$S$500="Yes")*'Internal Benchmark Data'!$I$4:$I$500*'Internal Benchmark Data'!$N$4:$N$500)+SUMPRODUCT(('External DB Benchmark Extract'!$B$4:$B$500=$B6)*('External DB Benchmark Extract'!$F$4:$F$500=$G6)*('External DB Benchmark Extract'!$G$4:$G$500=$H6)*('External DB Benchmark Extract'!$S$4:$S$500="Yes")*'External DB Benchmark Extract'!$I$4:$I$500*'External DB Benchmark Extract'!$N$4:$N$500))/$AB6,4),"")) -> 0.9721 | AK6: =IF($Y6<'Benchmark Settings'!$B$4,"",IFERROR(ROUND((SUMPRODUCT(('Internal Benchmark Data'!$B$4:$B$500=$B6)*('Internal Benchmark Data'!$F$4:$F$500=$G6)*('Internal Benchmark Data'!$G$4:$G$500=$H6)*('Internal Benchmark Data'!$S$4:$S$500="Yes")*'Internal Benchmark Data'!$K$4:$K$500*'Internal Benchmark Data'!$N$4:$N$500)+SUMPRODUCT(('External DB Benchmark Extract'!$B$4:$B$500=$B6)*('External DB Benchmark Extract'!$F$4:$F$500=$G6)*('External DB Benchmark Extract'!$G$4:$G$500=$H6)*('External DB Benchmark Extract'!$S$4:$S$500="Yes")*'External DB Benchmark Extract'!$K$4:$K$500*'External DB Benchmark Extract'!$N$4:$N$500))/$AB6,2),"")) -> 5.06 | AL6: =IFERROR(VLOOKUP($M6,'Index Table'!$A:$C,3,FALSE()),'Benchmark Settings'!$B$20) -> 118 | AM6: =IF($Y6<'Benchmark Settings'!$B$4,"",IFERROR(ROUND((SUMPRODUCT(('Internal Benchmark Data'!$B$4:$B$500=$B6)*('Internal Benchmark Data'!$F$4:$F$500=$G6)*('Internal Benchmark Data'!$G$4:$G$500=$H6)*('Internal Benchmark Data'!$S$4:$S$500="Yes")*'Internal Benchmark Data'!$R$4:$R$500*'Internal Benchmark Data'!$N$4:$N$500)+SUMPRODUCT(('External DB Benchmark Extract'!$B$4:$B$500=$B6)*('External DB Benchmark Extract'!$F$4:$F$500=$G6)*('External DB Benchmark Extract'!$G$4:$G$500=$H6)*('External DB Benchmark Extract'!$S$4:$S$500="Yes")*'External DB Benchmark Extract'!$R$4:$R$500*'External DB Benchmark Extract'!$N$4:$N$500))/$AB6,2),"")) -> 111.75 | AN6: =IF($Y6<'Benchmark Settings'!$B$4,"",IF($AF6="","",IFERROR(ROUND(MAX('Benchmark Settings'!$B$8,MIN('Benchmark Settings'!$B$9,POWER($F6/$AG6,-'Benchmark Settings'!$B$7))),4),1))) -> 1.0238 | AO6: =IF($Y6<'Benchmark Settings'!$B$4,"",IF($AF6="","",IFERROR(ROUND(MAX('Benchmark Settings'!$B$12,MIN('Benchmark Settings'!$B$13,1+(($J6-$AH6)*'Benchmark Settings'!$B$11))),4),1))) -> 1.0114 | AP6: =IF($Y6<'Benchmark Settings'!$B$4,"",IF($AF6="","",IFERROR(ROUND($AI6/$AJ6,4),1))) -> 1.0287 | AQ6: =IF($Y6<'Benchmark Settings'!$B$4,"",IF($AF6="","",IFERROR(ROUND(MAX('Benchmark Settings'!$B$16,MIN('Benchmark Settings'!$B$17,1+(($L6-$AK6)*'Benchmark Settings'!$B$15))),4),1))) -> 0.9985 | AR6: =IF($Y6<'Benchmark Settings'!$B$4,"",IF($AF6="","",IFERROR(ROUND($AL6/$AM6,4),1))) -> 1.0559 | AS6: =IF($Y6<'Benchmark Settings'!$B$4,"",IF($AF6="","",IFERROR(ROUND($AF6*$AN6*$AO6*$AP6*$AQ6*$AR6,2),""))) -> 19.19 | AT6: =($N6*$F6)+$O6+$P6+$Q6+$R6-$S6 -> 5725 | AU6: =IF($AS6="","",$AS6*$F6+$O6+$P6+$Q6+$R6-$S6) -> 5897.5 | AV6: =IF($AS6="","",ROUND($N6-$AS6,2)) -> -0.69 | AW6: =IF($AS6="","",IFERROR(ROUND($AV6/$AS6,4),"")) -> -0.036 | AX6: =IF($AU6="","",ROUND($AT6-$AU6,0)) -> -173 | AY6: =IF($Y6<'Benchmark Settings'!$B$4,"",ROUND($AN6*$AO6*$AP6*$AQ6*$AR6,4)) -> 1.123 | AZ6: =IF($Y6=0,"No Data",IF($Y6<'Benchmark Settings'!$B$4,"Insufficient",IF($Y6>=10,"HIGH",IF($Y6>=6,"MEDIUM","LOW")))) -> HIGH
